Workbook

Sheet 従業員情報
A1: 社員番号 | B1: 氏名 | C1: フリガナ | D1: 性別 | E1: 部門コード | F1: 部門名称 | G1: 生年月日 | H1: 年齢 | I1: 入社日 | J1: 退職日 | K1: 給与基本開始年月 | L1: 給与体系コード | M1: 給与体系名称 | N1: 事業所パターン | O1: 事業所名称 | P1: 従業員区分 | Q1: 雇用保険 | R1: 労災保険 | S1: 税区分 | T1: 所得者区分 | U1: 障害者区分 | V1: 勤労学生 | W1: 災害者 | X1: 社保労働 | Y1: 賞与報酬 | Z1: 固定締日 | AA1: 固定締日Ｐ | AB1: 変動締日 | AC1: 変動締日Ｐ | AD1: 給与計算フラグ | AE1: 賞与計算フラグ | AF1: 年末調整フラグ | AG1: 社会保険フラグ | AH1: 育児休業社保免除 | AI1: 勤怠取込除外者フラグ | AJ1: 所得金額調整控除対象 | AK1: 介護保険特定被保険者 | AL1: 介護保険適用除外者
A2: 6122 | B2: 長島 峯 | C2: ﾅｶﾞｼﾏ ﾐﾈ | D2: 女性 | E2: 100 | F2: 顧問 | G2: 17133 | H2: 77 | I2: 38858 | K2: 42278 | L2: 40 | M2: 顧嘱託 | N2: 2 | O2: 三輪精機株式会社顧問 | P2: 常用 | Q2: 非対象 | R2: 非対象 | S2: 甲欄 | T2: 一般 | U2: 非対象 | V2: 非対象 | W2: 非対象 | X2: 給与体系 | Y2: 給与体系に準ずる | Z2: 31 | AA2: 前月 | AB2: 31 | AC2: 前月 | AD2: 計算する | AE2: 計算しない | AF2: 計算しない | AG2: 計算しない | AH2: なし | AI2: なし | AJ2: 非対象 | AK2: 非対象 | AL2: 非対象
A3: 6123 | B3: 西海 孝夫 | C3: ﾆｼｳﾐ ﾀｶｵ | D3: 男性 | E3: 100 | F3: 顧問 | H3: 0 | I3: 38930 | K3: 42278 | L3: 40 | M3: 顧嘱託 | N3: 2 | O3: 三輪精機株式会社顧問 | P3: 常用 | Q3: 非対象 | R3: 非対象 | S3: 甲欄 | T3: 一般 | U3: 非対象 | V3: 非対象 | W3: 非対象 | X3: 給与体系 | Y3: 給与体系に準ずる | Z3: 31 | AA3: 前月 | AB3: 31 | AC3: 前月 | AD3: 計算する | AE3: 計算しない | AF3: 計算しない | AG3: 計算しない | AH3: なし | AI3: なし | AJ3: 非対象 | AK3: 非対象 | AL3: 非対象
A4: 6127 | B4: 長島 利一 | C4: ﾅｶﾞｼﾏ ﾘｲﾁ | D4: 男性 | E4: 100 | F4: 顧問 | G4: 17225 | H4: 76 | I4: 39173 | K4: 42278 | L4: 40 | M4: 顧嘱託 | N4: 2 | O4: 三輪精機株式会社顧問 | P4: 常用 | Q4: 非対象 | R4: 非対象 | S4: 甲欄 | T4: 一般 | U4: 非対象 | V4: 非対象 | W4: 非対象 | X4: 給与体系 | Y4: 給与体系に準ずる | Z4: 31 | AA4: 前月 | AB4: 31 | AC4: 前月 | AD4: 計算する | AE4: 計算しない | AF4: 計算しない | AG4: 計算しない | AH4: なし | AI4: なし | AJ4: 非対象 | AK4: 非対象 | AL4: 非対象
A5: 6130 | B5: 宮島 文夫 | C5: ﾐﾔｼﾞﾏ ﾌﾐｵ | D5: 男性 | E5: 100 | F5: 顧問 | G5: 18841 | H5: 72 | I5: 41275 | K5: 42278 | L5: 40 | M5: 顧嘱託 | N5: 2 | O5: 三輪精機株式会社顧問 | P5: 常用 | Q5: 非対象 | R5: 非対象 | S5: 甲欄 | T5: 一般 | U5: 非対象 | V5: 非対象 | W5: 非対象 | X5: 給与体系 | Y5: 給与体系に準ずる | Z5: 31 | AA5: 前月 | AB5: 31 | AC5: 前月 | AD5: 計算する | AE5: 計算しない | AF5: 計算しない | AG5: 計算しない | AH5: なし | AI5: なし | AJ5: 非対象 | AK5: 非対象 | AL5: 非対象
A6: 6134 | B6: 鈴木 孝幸 | C6: ｽｽﾞｷ ﾀｶﾕｷ | D6: 男性 | E6: 100 | F6: 顧問 | G6: 14946 | H6: 83 | I6: 42614 | K6: 42644 | L6: 40 | M6: 顧嘱託 | N6: 3 | O6: 三輪精機株式会社役員 | P6: 常用 | Q6: 非対象 | R6: 非対象 | S6: 乙欄 | T6: 一般 | U6: 非対象 | V6: 非対象 | W6: 非対象 | X6: 給与体系 | Y6: 給与体系に準ずる | Z6: 31 | AA6: 前月 | AB6: 31 | AC6: 前月 | AD6: 計算する | AE6: 計算する | AF6: 計算しない | AG6: 計算しない | AH6: なし | AI6: なし | AJ6: 非対象 | AK6: 非対象 | AL6: 非対象
A7: 6135 | B7: 佐藤 浩二 | C7: ｻﾄｳ ｺｳｼﾞ | D7: 男性 | E7: 100 | F7: 顧問 | G7: 20342 | H7: 68 | I7: 43864 | K7: 44652 | L7: 95 | M7: 役員 | N7: 2 | O7: 三輪精機株式会社顧問 | P7: 常用 | Q7: 被保険者 | R7: 対象 | S7: 甲欄 | T7: 一般 | U7: 非対象 | V7: 非対象 | W7: 非対象 | X7: 給与体系 | Y7: 給与体系に準ずる | Z7: 31 | AA7: 前月 | AB7: 31 | AC7: 前月 | AD7: 計算しない | AE7: 計算しない | AF7: 計算しない | AG7: 計算しない | AH7: なし | AI7: なし | AJ7: 非対象 | AK7: 非対象 | AL7: 非対象
A8: 6137 | B8: 西海 絹子 | C8: ﾆｼｳﾐ ｷﾇｺ | D8: 女性 | G8: 17396 | H8: 76 | I8: 44927 | K8: 44927 | L8: 95 | M8: 役員 | N8: 3 | O8: 三輪精機株式会社役員 | P8: 常用 | Q8: 非対象 | R8: 非対象 | S8: 甲欄 | T8: 一般 | U8: 非対象 | V8: 非対象 | W8: 非対象 | X8: 給与体系 | Y8: 給与体系に準ずる | Z8: 31 | AA8: 前月 | AB8: 31 | AC8: 前月 | AD8: 計算しない | AE8: 計算しない | AF8: 計算しない | AG8: 計算しない | AH8: なし | AI8: なし | AJ8: 非対象 | AK8: 非対象 | AL8: 非対象
A9: 2820 | B9: 茂木 健 | C9: ﾓｷﾞ ﾀｹｼ | D9: 男性 | E9: 80000 | F9: ＮＥＬ | G9: 24130 | H9: 58 | I9: 32226 | K9: 43191 | L9: 95 | M9: 役員 | N9: 3 | O9: 三輪精機株式会社役員 | P9: 常用 | Q9: 被保険者 | R9: 対象 | S9: 甲欄 | T9: 一般 | U9: 非対象 | V9: 非対象 | W9: 非対象 | X9: 給与体系 | Y9: 給与体系に準ずる | Z9: 31 | AA9: 前月 | AB9: 31 | AC9: 前月 | AD9: 計算しない | AE9: 計算しない | AF9: 計算しない | AG9: 計算しない | AH9: なし | AI9: なし | AJ9: 非対象 | AK9: 非対象 | AL9: 非対象
A10: 3019 | B10: 桐山 尚也 | C10: ｷﾘﾔﾏ ﾅｵﾔ | D10: 男性 | E10: 51000 | F10: 品質保証部品質管理課 | G10: 26640 | H10: 51 | I10: 34780 | K10: 42278 | L10: 20 | M10: 月給者 | N10: 1 | O10: 三輪精機株式会社 | P10: 常用 | Q10: 被保険者 | R10: 対象 | S10: 甲欄 | T10: 一般 | U10: 非対象 | V10: 非対象 | W10: 非対象 | X10: 給与体系 | Y10: 給与体系に準ずる | Z10: 31 | AA10: 前月 | AB10: 31 | AC10: 前月 | AD10: 計算する | AE10: 計算する | AF10: 計算する | AG10: 計算する | AH10: なし | AI10: なし | AJ10: 非対象 | AK10: 非対象 | AL10: 非対象
A11: 3084 | B11: 新井 慎吾 | C11: ｱﾗｲ ｼﾝｺﾞ | D11: 男性 | E11: 63000 | F11: 品質保証部（羽生） | G11: 26669 | H11: 51 | I11: 34780 | K11: 42278 | L11: 20 | M11: 月給者 | N11: 1 | O11: 三輪精機株式会社 | P11: 常用 | Q11: 被保険者 | R11: 対象 | S11: 甲欄 | T11: 一般 | U11: 非対象 | V11: 非対象 | W11: 非対象 | X11: 給与体系 | Y11: 給与体系に準ずる | Z11: 31 | AA11: 前月 | AB11: 31 | AC11: 前月 | AD11: 計算する | AE11: 計算する | AF11: 計算する | AG11: 計算する | AH11: なし | AI11: なし | AJ11: 非対象 | AK11: 非対象 | AL11: 非対象
A12: 1339 | B12: 橋本 誠 | C12: ﾊｼﾓﾄ ﾏｺﾄ | D12: 男性 | E12: 63000 | F12: 品質保証部（羽生） | G12: 27250 | H12: 49 | I12: 38777 | K12: 42278 | L12: 20 | M12: 月給者 | N12: 1 | O12: 三輪精機株式会社 | P12: 常用 | Q12: 被保険者 | R12: 対象 | S12: 甲欄 | T12: 一般 | U12: 非対象 | V12: 非対象 | W12: 非対象 | X12: 給与体系 | Y12: 給与体系に準ずる | Z12: 31 | AA12: 前月 | AB12: 31 | AC12: 前月 | AD12: 計算する | AE12: 計算する | AF12: 計算する | AG12: 計算する | AH12: なし | AI12: なし | AJ12: 非対象 | AK12: 非対象 | AL12: 非対象
A13: 1412 | B13: 石井 達矢 | C13: ｲｼｲ ﾀﾂﾔ | D13: 男性 | E13: 63000 | F13: 品質保証部（羽生） | G13: 24538 | H13: 56 | I13: 44378 | K13: 44166 | L13: 20 | M13: 月給者 | N13: 1 | O13: 三輪精機株式会社 | P13: 常用 | Q13: 被保険者 | R13: 対象 | S13: 甲欄 | T13: 一般 | U13: 非対象 | V13: 非対象 | W13: 非対象 | X13: 給与体系 | Y13: 給与体系に準ずる | Z13: 31 | AA13: 前月 | AB13: 31 | AC13: 前月 | AD13: 計算する | AE13: 計算する | AF13: 計算する | AG13: 計算する | AH13: なし | AI13: なし | AJ13: 非対象 | AK13: 非対象 | AL13: 非対象
A14: 3320 | B14: 沢出 滋 | C14: ｻﾜｲﾃﾞ ｼｹﾞﾙ | D14: 男性 | E14: 63000 | F14: 品質保証部（羽生） | G14: 31896 | H14: 36 | I14: 40258 | K14: 42278 | L14: 20 | M14: 月給者 | N14: 1 | O14: 三輪精機株式会社 | P14: 常用 | Q14: 被保険者 | R14: 対象 | S14: 甲欄 | T14: 一般 | U14: 非対象 | V14: 非対象 | W14: 非対象 | X14: 給与体系 | Y14: 給与体系に準ずる | Z14: 31 | AA14: 前月 | AB14: 31 | AC14: 前月 | AD14: 計算する | AE14: 計算する | AF14: 計算する | AG14: 計算する | AH14: なし | AI14: なし | AJ14: 非対象 | AK14: 非対象 | AL14: 非対象
A15: 3431 | B15: 菊地 悠太 | C15: ｷｸﾁ ﾕｳﾀ | D15: 男性 | E15: 63000 | F15: 品質保証部（羽生） | G15: 33827 | H15: 31 | I15: 42095 | K15: 42278 | L15: 20 | M15: 月給者 | N15: 1 | O15: 三輪精機株式会社 | P15: 常用 | Q15: 被保険者 | R15: 対象 | S15: 甲欄 | T15: 一般 | U15: 非対象 | V15: 非対象 | W15: 非対象 | X15: 給与体系 | Y15: 給与体系に準ずる | Z15: 31 | AA15: 前月 | AB15: 31 | AC15: 前月 | AD15: 計算する | AE15: 計算する | AF15: 計算する | AG15: 計算する | AH15: なし | AI15: なし | AJ15: 非対象 | AK15: 非対象 | AL15: 非対象
A16: 3950 | B16: 川島 洋子 | C16: ｶﾜｼﾏ ﾖｳｺ | D16: 女性 | E16: 63000 | F16: 品質保証部（羽生） | G16: 25397 | H16: 54 | I16: 38769 | K16: 42278 | L16: 20 | M16: 月給者 | N16: 1 | O16: 三輪精機株式会社 | P16: 常用 | Q16: 被保険者 | R16: 対象 | S16: 甲欄 | T16: 寡婦 | U16: 非対象 | V16: 非対象 | W16: 非対象 | X16: 給与体系 | Y16: 給与体系に準ずる | Z16: 31 | AA16: 前月 | AB16: 31 | AC16: 前月 | AD16: 計算する | AE16: 計算する | AF16: 計算する | AG16: 計算する | AH16: なし | AI16: なし | AJ16: 非対象 | AK16: 非対象 | AL16: 非対象
A17: 1423 | B17: 佐々木 祐太 | C17: ｻｻｷ ﾕｳﾀ | D17: 男性 | E17: 63000 | F17: 品質保証部（羽生） | G17: 34901 | H17: 28 | I17: 44621 | K17: 44652 | L17: 20 | M17: 月給者 | N17: 1 | O17: 三輪精機株式会社 | P17: 常用 | Q17: 被保険者 | R17: 対象 | S17: 甲欄 | T17: 一般 | U17: 非対象 | V17: 非対象 | W17: 非対象 | X17: 給与体系 | Y17: 給与体系に準ずる | Z17: 31 | AA17: 前月 | AB17: 31 | AC17: 前月 | AD17: 計算する | AE17: 計算する | AF17: 計算する | AG17: 計算する | AH17: なし | AI17: なし | AJ17: 非対象 | AK17: 非対象 | AL17: 非対象
A18: 3380 | B18: 吉崎 涼 | C18: ﾖｼｻﾞｷ ﾘﾖｳ | D18: 男性 | E18: 63000 | F18: 品質保証部（羽生） | G18: 34150 | H18: 30 | I18: 40989 | K18: 42278 | L18: 20 | M18: 月給者 | N18: 1 | O18: 三輪精機株式会社 | P18: 常用 | Q18: 被保険者 | R18: 対象 | S18: 甲欄 | T18: 一般 | U18: 非対象 | V18: 非対象 | W18: 非対象 | X18: 給与体系 | Y18: 給与体系に準ずる | Z18: 31 | AA18: 前月 | AB18: 31 | AC18: 前月 | AD18: 計算する | AE18: 計算する | AF18: 計算する | AG18: 計算する | AH18: なし | AI18: なし | AJ18: 非対象 | AK18: 非対象 | AL18: 非対象
A19: 3537 | B19: 針谷 大和 | C19: ﾊﾘｶﾞﾔ ﾀｲﾄ | D19: 男性 | E19: 63000 | F19: 品質保証部（羽生） | G19: 36807 | H19: 23 | I19: 45017 | K19: 45047 | L19: 20 | M19: 月給者 | N19: 1 | O19: 三輪精機株式会社 | P19: 常用 | Q19: 被保険者 | R19: 対象 | S19: 甲欄 | T19: 一般 | U19: 非対象 | V19: 非対象 | W19: 非対象 | X19: 給与体系 | Y19: 給与体系に準ずる | Z19: 31 | AA19: 前月 | AB19: 31 | AC19: 前月 | AD19: 計算する | AE19: 計算する | AF19: 計算する | AG19: 計算する | AH19: なし | AI19: なし | AJ19: 非対象 | AK19: 非対象 | AL19: 非対象
A20: 5062 | B20: 鈴木 昇 | C20: ｽｽﾞｷ ﾉﾎﾞﾙ | D20: 男性 | E20: 63000 | F20: 品質保証部（羽生） | G20: 24323 | H20: 57 | I20: 30035 | K20: 42278 | L20: 20 | M20: 月給者 | N20: 1 | O20: 三輪精機株式会社 | P20: 常用 | Q20: 被保険者 | R20: 対象 | S20: 甲欄 | T20: 一般 | U20: 非対象 | V20: 非対象 | W20: 非対象 | X20: 給与体系 | Y20: 給与体系に準ずる | Z20: 31 | AA20: 前月 | AB20: 31 | AC20: 前月 | AD20: 計算する | AE20: 計算する | AF20: 計算する | AG20: 計算する | AH20: なし | AI20: なし | AJ20: 非対象 | AK20: 非対象 | AL20: 非対象
... A35: 3392 | B35: 木下 由紀子 | C35: ｷｼﾀ ﾕｷｺ | D35: 女性 | E35: 3000 | F35: 経営管理部 | G35: 33305 | H35: 32 | I35: 41354 | K35: 42278 | L35: 20 | M35: 月給者 | N35: 1 | O35: 三輪精機株式会社 | P35: 常用 | Q35: 被保険者 | R35: 対象 | S35: 甲欄 | T35: 一般 | U35: 非対象 | V35: 非対象 | W35: 非対象 | X35: 給与体系 | Y35: 給与体系に準ずる | Z35: 31 | AA35: 前月 | AB35: 31 | AC35: 前月 | AD35: 計算する | AE35: 計算する | AF35: 計算する | AG35: 計算する | AH35: なし | AI35: なし | AJ35: 非対象 | AK35: 非対象 | AL35: 非対象
A36: 1307 | B36: 西海 栄一 | C36: ﾆｼｳﾐ ｴｲｲﾁ | D36: 男性 | G36: 26766 | H36: 50 | I36: 36251 | K36: 42278 | L36: 95 | M36: 役員 | N36: 3 | O36: 三輪精機株式会社役員 | P36: 常用 | Q36: 非対象 | R36: 非対象 | S36: 甲欄 | T36: 一般 | U36: 非対象 | V36: 非対象 | W36: 非対象 | X36: 給与体系 | Y36: 給与体系に準ずる | Z36: 31 | AA36: 前月 | AB36: 31 | AC36: 前月 | AD36: 計算する | AE36: 計算する | AF36: 計算する | AG36: 計算する | AH36: なし | AI36: なし | AJ36: 非対象 | AK36: 非対象 | AL36: 非対象
A37: 1420 | B37: 三原 繁一 | C37: ﾐﾊﾗ ｼｹﾞｶｽﾞ | D37: 男性 | E37: 1000 | F37: 人事部 | G37: 27963 | H37: 47 | I37: 44562 | K37: 44562 | L37: 20 | M37: 月給者 | N37: 1 | O37: 三輪精機株式会社 | P37: 常用 | Q37: 被保険者 | R37: 対象 | S37: 甲欄 | T37: 一般 | U37: 非対象 | V37: 非対象 | W37: 非対象 | X37: 給与体系 | Y37: 給与体系に準ずる | Z37: 31 | AA37: 前月 | AB37: 31 | AC37: 前月 | AD37: 計算する | AE37: 計算する | AF37: 計算する | AG37: 計算する | AH37: なし | AI37: なし | AJ37: 非対象 | AK37: 非対象 | AL37: 非対象
A38: 2497 | B38: 時田 俊彦 | C38: ﾄｷﾀﾄｼﾋｺ | D38: 男性 | E38: 30000 | F38: 生産技術部１課 | G38: 20142 | H38: 68 | I38: 28564 | K38: 42278 | L38: 95 | M38: 役員 | N38: 1 | O38: 三輪精機株式会社 | P38: 常用 | Q38: 非対象 | R38: 非対象 | S38: 甲欄 | T38: 一般 | U38: 非対象 | V38: 非対象 | W38: 非対象 | X38: 給与体系 | Y38: 給与体系に準ずる | Z38: 31 | AA38: 前月 | AB38: 31 | AC38: 前月 | AD38: 計算しない | AE38: 計算しない | AF38: 計算しない | AG38: 計算しない | AH38: なし | AI38: なし | AJ38: 非対象 | AK38: 非対象 | AL38: 非対象
A39: 6136 | B39: 富山 敦子 | C39: ﾄﾐﾔﾏ ｱﾂｺ | D39: 女性 | E39: 1020 | F39: 人事部 | G39: 21072 | H39: 66 | I39: 44242 | K39: 44256 | L39: 70 | M39: ﾊﾟｰﾄ失 | N39: 1 | O39: 三輪精機株式会社 | P39: 常用 | Q39: 被保険者 | R39: 対象 | S39: 甲欄 | T39: 一般 | U39: 非対象 | V39: 非対象 | W39: 非対象 | X39: 給与体系 | Y39: 給与体系に準ずる | Z39: 31 | AA39: 前月 | AB39: 31 | AC39: 前月 | AD39: 計算する | AE39: 計算する | AF39: 計算する | AG39: 計算する | AH39: なし | AI39: なし | AJ39: 非対象 | AK39: 非対象 | AL39: 非対象
A40: 1376 | B40: 山本 剛史 | C40: ﾔﾏﾓﾄ ﾏｻｼ | D40: 男性 | E40: 1000 | F40: 人事部 | G40: 29924 | H40: 42 | I40: 40960 | K40: 45200 | L40: 20 | M40: 月給者 | N40: 1 | O40: 三輪精機株式会社 | P40: 常用 | Q40: 被保険者 | R40: 対象 | S40: 甲欄 | T40: 一般 | U40: 非対象 | V40: 非対象 | W40: 非対象 | X40: 給与体系 | Y40: 給与体系に準ずる | Z40: 31 | AA40: 前月 | AB40: 31 | AC40: 前月 | AD40: 計算する | AE40: 計算する | AF40: 計算する | AG40: 計算する | AH40: なし | AI40: なし | AJ40: 非対象 | AK40: 非対象 | AL40: 非対象
A41: 3375 | B41: 立花 舞 | C41: ﾀﾁﾊﾞﾅ ﾏｲ | D41: 女性 | E41: 1000 | F41: 人事部 | G41: 34308 | H41: 30 | I41: 40989 | K41: 44713 | L41: 20 | M41: 月給者 | N41: 1 | O41: 三輪精機株式会社 | P41: 常用 | Q41: 被保険者 | R41: 対象 | S41: 甲欄 | T41: 一般 | U41: 非対象 | V41: 非対象 | W41: 非対象 | X41: 給与体系 | Y41: 給与体系に準ずる | Z41: 31 | AA41: 前月 | AB41: 31 | AC41: 前月 | AD41: 計算する | AE41: 計算する | AF41: 計算する | AG41: 計算する | AH41: なし | AI41: なし | AJ41: 非対象 | AK41: 非対象 | AL41: 非対象
A42: 1399 | B42: 松原 幸生 | C42: ﾏﾂﾊﾞﾗ ｻｷｵ | D42: 男性 | E42: 1000 | F42: 人事部 | G42: 24273 | H42: 57 | I42: 43374 | K42: 43405 | L42: 20 | M42: 月給者 | N42: 1 | O42: 三輪精機株式会社 | P42: 常用 | Q42: 被保険者 | R42: 対象 | S42: 甲欄 | T42: 一般 | U42: 非対象 | V42: 非対象 | W42: 非対象 | X42: 給与体系 | Y42: 給与体系に準ずる | Z42: 31 | AA42: 前月 | AB42: 31 | AC42: 前月 | AD42: 計算する | AE42: 計算する | AF42: 計算する | AG42: 計算する | AH42: なし | AI42: なし | AJ42: 非対象 | AK42: 非対象 | AL42: 非対象
A43: 3545 | B43: 今村 哲朗 | C43: ｲﾏﾑﾗ ﾃﾂﾛｳ | D43: 男性 | E43: 1000 | F43: 人事部 | G43: 36889 | H43: 23 | I43: 45017 | K43: 45047 | L43: 20 | M43: 月給者 | N43: 1 | O43: 三輪精機株式会社 | P43: 常用 | Q43: 被保険者 | R43: 対象 | S43: 甲欄 | T43: 一般 | U43: 一般障害 | V43: 非対象 | W43: 非対象 | X43: 給与体系 | Y43: 給与体系に準ずる | Z43: 31 | AA43: 前月 | AB43: 31 | AC43: 前月 | AD43: 計算する | AE43: 計算する | AF43: 計算する | AG43: 計算する | AH43: なし | AI43: なし | AJ43: 非対象 | AK43: 非対象 | AL43: 非対象
A44: 3936 | B44: 井出 雄三 | C44: ｲﾃﾞ ﾕｳｿﾞｳ | D44: 男性 | E44: 1000 | F44: 人事部 | G44: 28377 | H44: 46 | I44: 38769 | K44: 45261 | L44: 20 | M44: 月給者 | N44: 1 | O44: 三輪精機株式会社 | P44: 常用 | Q44: 被保険者 | R44: 対象 | S44: 甲欄 | T44: 一般 | U44: 非対象 | V44: 非対象 | W44: 非対象 | X44: 給与体系 | Y44: 給与体系に準ずる | Z44: 31 | AA44: 前月 | AB44: 31 | AC44: 前月 | AD44: 計算する | AE44: 計算する | AF44: 計算する | AG44: 計算する | AH44: なし | AI44: なし | AJ44: 非対象 | AK44: 非対象 | AL44: 非対象
A45: 1408 | B45: 老沼 信彦 | C45: ｵｲﾇﾏ ﾉﾌﾞﾋｺ | D45: 男性 | E45: 1100 | F45: 人事部羽生 | G45: 23097 | H45: 60 | I45: 43934 | K45: 43952 | L45: 20 | M45: 月給者 | N45: 1 | O45: 三輪精機株式会社 | P45: 常用 | Q45: 被保険者 | R45: 対象 | S45: 甲欄 | T45: 一般 | U45: 非対象 | V45: 非対象 | W45: 非対象 | X45: 給与体系 | Y45: 給与体系に準ずる | Z45: 31 | AA45: 前月 | AB45: 31 | AC45: 前月 | AD45: 計算する | AE45: 計算する | AF45: 計算する | AG45: 計算する | AH45: なし | AI45: なし | AJ45: 非対象 | AK45: 非対象 | AL45: 非対象
A46: 3002 | B46: 堤 松子 | C46: ﾂﾂﾐ ｼｮｳｺ | D46: 女性 | E46: 1100 | F46: 人事部羽生 | G46: 27782 | H46: 48 | I46: 34415 | K46: 42278 | L46: 20 | M46: 月給者 | N46: 1 | O46: 三輪精機株式会社 | P46: 常用 | Q46: 被保険者 | R46: 対象 | S46: 甲欄 | T46: 一般 | U46: 非対象 | V46: 非対象 | W46: 非対象 | X46: 給与体系 | Y46: 給与体系に準ずる | Z46: 31 | AA46: 前月 | AB46: 31 | AC46: 前月 | AD46: 計算する | AE46: 計算する | AF46: 計算する | AG46: 計算する | AH46: なし | AI46: なし | AJ46: 非対象 | AK46: 非対象 | AL46: 非対象
A47: 3415 | B47: 味志 康平 | C47: ｱｼﾞｼ ｺｳﾍｲ | D47: 男性 | E47: 1100 | F47: 人事部羽生 | G47: 32694 | H47: 34 | I47: 41719 | K47: 42278 | L47: 20 | M47: 月給者 | N47: 1 | O47: 三輪精機株式会社 | P47: 常用 | Q47: 被保険者 | R47: 対象 | S47: 甲欄 | T47: 一般 | U47: 非対象 | V47: 非対象 | W47: 非対象 | X47: 給与体系 | Y47: 給与体系に準ずる | Z47: 31 | AA47: 前月 | AB47: 31 | AC47: 前月 | AD47: 計算する | AE47: 計算する | AF47: 計算する | AG47: 計算する | AH47: なし | AI47: なし | AJ47: 非対象 | AK47: 非対象 | AL47: 非対象
A48: 1291 | B48: 石塚 隆司 | C48: ｲｼﾂﾞｶ ﾘﾕｳｼﾞ | D48: 男性 | G48: 24777 | H48: 56 | I48: 34415 | K48: 44593 | L48: 95 | M48: 役員 | N48: 3 | O48: 三輪精機株式会社役員 | P48: 常用 | Q48: 被保険者 | R48: 対象 | S48: 甲欄 | T48: 一般 | U48: 非対象 | V48: 非対象 | W48: 非対象 | X48: 給与体系 | Y48: 給与体系に準ずる | Z48: 31 | AA48: 前月 | AB48: 31 | AC48: 前月 | AD48: 計算しない | AE48: 計算しない | AF48: 計算しない | AG48: 計算しない | AH48: なし | AI48: なし | AJ48: 非対象 | AK48: 非対象 | AL48: 非対象
A49: 1367 | B49: 外山 亮司 | C49: ﾄﾔﾏ ﾘﾖｳｼﾞ | D49: 男性 | E49: 10000 | F49: 営業部 | G49: 25576 | H49: 54 | I49: 40513 | K49: 44531 | L49: 20 | M49: 月給者 | N49: 3 | O49: 三輪精機株式会社役員 | P49: 常用 | Q49: 被保険者 | R49: 対象 | S49: 甲欄 | T49: 一般 | U49: 非対象 | V49: 非対象 | W49: 非対象 | X49: 給与体系 | Y49: 給与体系に準ずる | Z49: 31 | AA49: 前月 | AB49: 31 | AC49: 前月 | AD49: 計算しない | AE49: 計算しない | AF49: 計算しない | AG49: 計算しない | AH49: なし | AI49: なし | AJ49: 非対象 | AK49: 非対象 | AL49: 非対象
A50: 2515 | B50: 秋山 久 | C50: ｱｷﾔﾏﾋｻｼ | D50: 男性 | E50: 30000 | F50: 生産技術部１課 | G50: 20645 | H50: 67 | I50: 28937 | K50: 42278 | L50: 95 | M50: 役員 | N50: 3 | O50: 三輪精機株式会社役員 | P50: 常用 | Q50: 非対象 | R50: 非対象 | S50: 甲欄 | T50: 一般 | U50: 非対象 | V50: 非対象 | W50: 非対象 | X50: 給与体系 | Y50: 給与体系に準ずる | Z50: 31 | AA50: 前月 | AB50: 31 | AC50: 前月 | AD50: 計算しない | AE50: 計算しない | AF50: 計算しない | AG50: 計算しない | AH50: なし | AI50: なし | AJ50: 非対象 | AK50: 非対象 | AL50: 非対象
A51: 1323 | B51: 戸田 鉄也 | C51: ﾄﾀﾞ ﾃﾂﾔ | D51: 男性 | E51: 10000 | F51: 営業部 | G51: 26590 | H51: 51 | I51: 37747 | K51: 42278 | L51: 20 | M51: 月給者 | N51: 1 | O51: 三輪精機株式会社 | P51: 常用 | Q51: 被保険者 | R51: 対象 | S51: 甲欄 | T51: 一般 | U51: 非対象 | V51: 非対象 | W51: 非対象 | X51: 給与体系 | Y51: 給与体系に準ずる | Z51: 31 | AA51: 前月 | AB51: 31 | AC51: 前月 | AD51: 計算する | AE51: 計算する | AF51: 計算する | AG51: 計算する | AH51: なし | AI51: なし | AJ51: 非対象 | AK51: 非対象 | AL51: 非対象
A52: 1397 | B52: 袴田 晴夫 | C52: ﾊｶﾏﾀﾞ ﾊﾙｵ | D52: 男性 | E52: 10000 | F52: 営業部 | G52: 29517 | H52: 43 | I52: 43160 | K52: 43191 | L52: 20 | M52: 月給者 | N52: 1 | O52: 三輪精機株式会社 | P52: 常用 | Q52: 被保険者 | R52: 対象 | S52: 甲欄 | T52: 一般 | U52: 非対象 | V52: 非対象 | W52: 非対象 | X52: 給与体系 | Y52: 給与体系に準ずる | Z52: 31 | AA52: 前月 | AB52: 31 | AC52: 前月 | AD52: 計算する | AE52: 計算する | AF52: 計算する | AG52: 計算する | AH52: なし | AI52: なし | AJ52: 非対象 | AK52: 非対象 | AL52: 非対象
A53: 3297 | B53: 羽鳥 麻里 | C53: ﾊﾄﾘ ﾏﾘ | D53: 女性 | E53: 10000 | F53: 営業部 | G53: 32945 | H53: 33 | I53: 39528 | K53: 42278 | L53: 20 | M53: 月給者 | N53: 1 | O53: 三輪精機株式会社 | P53: 常用 | Q53: 被保険者 | R53: 対象 | S53: 甲欄 | T53: 一般 | U53: 非対象 | V53: 非対象 | W53: 非対象 | X53: 給与体系 | Y53: 給与体系に準ずる | Z53: 31 | AA53: 前月 | AB53: 31 | AC53: 前月 | AD53: 計算する | AE53: 計算する | AF53: 計算する | AG53: 計算する | AH53: 免除する | AI53: なし | AJ53: 非対象 | AK53: 非対象 | AL53: 非対象
A54: 3491 | B54: 中村 友和 | C54: ﾅｶﾑﾗ ﾄﾓｶｽﾞ | D54: 男性 | E54: 10000 | F54: 営業部 | G54: 34813 | H54: 28 | I54: 43191 | K54: 43191 | L54: 20 | M54: 月給者 | N54: 1 | O54: 三輪精機株式会社 | P54: 常用 | Q54: 被保険者 | R54: 対象 | S54: 甲欄 | T54: 一般 | U54: 非対象 | V54: 非対象 | W54: 非対象 | X54: 給与体系 | Y54: 給与体系に準ずる | Z54: 31 | AA54: 前月 | AB54: 31 | AC54: 前月 | AD54: 計算する | AE54: 計算する | AF54: 計算する | AG54: 計算する | AH54: なし | AI54: なし | AJ54: 非対象 | AK54: 非対象 | AL54: 非対象
...

Sheet 202008
D2: 基準年月日
C3: 社員番号 | D3: 氏名 | E3: 性別 | F3: 生年月日 | J3: 入社 年月 | O3: 学歴 | P3: 部門 | Q3: 部門 | R3: 直間コード | S3: 直間コード | T3: 職専コード
G4: 44440 | P4: コード | Q4: 名
A5: 7 | B5: 62 | C5: 1410 | D5: 石田 詩織 | E5: L | F5: 19941107 | G5: =DATE(INT(F5/10000),INT(MOD(F5,10000)/100),MOD(F5,100)) -> 34645 | H5: =DATEDIF(G5,$G$4,"Y") -> 26 | J5: 20200922 | K5: =DATE(INT(J5/10000),INT(MOD(J5,10000)/100),MOD(J5,100)) -> 44096 | L5: =DATEDIF(K5,$G$4,"Y") -> 0 | O5: 8 | P5: 10000 | Q5: 営業部 | R5: 0 | T5: 2
A6: 20 | B6: 18 | C6: 1342 | D6: 阿保 裕子 | E6: L | F6: 19760731 | G6: =DATE(INT(F6/10000),INT(MOD(F6,10000)/100),MOD(F6,100)) -> 27972 | H6: =DATEDIF(G6,$G$4,"Y") -> 45 | J6: 20030123 | K6: =DATE(INT(J6/10000),INT(MOD(J6,10000)/100),MOD(J6,100)) -> 37644 | L6: =DATEDIF(K6,$G$4,"Y") -> 18 | O6: 7 | P6: 80000 | Q6: ＮＥＬ | R6: 0 | T6: 2
A7: 6 | B7: 229 | C7: 3297 | D7: 羽鳥 麻里 | E7: L | F7: 19900313 | G7: =DATE(INT(F7/10000),INT(MOD(F7,10000)/100),MOD(F7,100)) -> 32945 | H7: =DATEDIF(G7,$G$4,"Y") -> 31 | J7: 20080321 | K7: =DATE(INT(J7/10000),INT(MOD(J7,10000)/100),MOD(J7,100)) -> 39528 | L7: =DATEDIF(K7,$G$4,"Y") -> 13 | O7: 6 | P7: 10000 | Q7: 営業部 | R7: 0 | T7: 2
A8: 14 | B8: 286 | C8: 3406 | D8: 加藤 咲希 | E8: L | F8: 19950225 | G8: =DATE(INT(F8/10000),INT(MOD(F8,10000)/100),MOD(F8,100)) -> 34755 | H8: =DATEDIF(G8,$G$4,"Y") -> 26 | J8: 20130321 | K8: =DATE(INT(J8/10000),INT(MOD(J8,10000)/100),MOD(J8,100)) -> 41354 | L8: =DATEDIF(K8,$G$4,"Y") -> 8 | O8: 6 | P8: 66011 | Q8: 羽生工場ＶＰ－２ | R8: 1 | S8: ＊ | T8: 2
A9: 9 | B9: 22 | C9: 1348 | D9: 柿沼 千穂 | E9: L | F9: 19870922 | G9: =DATE(INT(F9/10000),INT(MOD(F9,10000)/100),MOD(F9,100)) -> 32042 | H9: =DATEDIF(G9,$G$4,"Y") -> 33 | J9: 20080321 | K9: =DATE(INT(J9/10000),INT(MOD(J9,10000)/100),MOD(J9,100)) -> 39528 | L9: =DATEDIF(K9,$G$4,"Y") -> 13 | O9: 6 | P9: 64111 | Q9: 羽生工場ＢＢ | R9: 1 | S9: ＊ | T9: 2
A10: 11 | B10: 314 | C10: 3450 | D10: 柿沼 優花 | E10: L | F10: 19960920 | G10: =DATE(INT(F10/10000),INT(MOD(F10,10000)/100),MOD(F10,100)) -> 35328 | H10: =DATEDIF(G10,$G$4,"Y") -> 24 | J10: 20150401 | K10: =DATE(INT(J10/10000),INT(MOD(J10,10000)/100),MOD(J10,100)) -> 42095 | L10: =DATEDIF(K10,$G$4,"Y") -> 6 | O10: 6 | P10: 65011 | Q10: 羽生工場ＶＰ－１ | R10: 1 | S10: ＊ | T10: 2
A11: 6 | B11: 154 | C11: 3093 | D11: 岩永 朋子 | E11: L | F11: 19750430 | G11: =DATE(INT(F11/10000),INT(MOD(F11,10000)/100),MOD(F11,100)) -> 27514 | H11: =DATEDIF(G11,$G$4,"Y") -> 46 | J11: 19960321 | K11: =DATE(INT(J11/10000),INT(MOD(J11,10000)/100),MOD(J11,100)) -> 35145 | L11: =DATEDIF(K11,$G$4,"Y") -> 25 | O11: 7 | P11: 40000 | Q11: 本社工場工場管理課 | R11: 0 | T11: 2
A12: 3 | B12: 172 | C12: 3161 | D12: 岩瀬 安奈 | E12: L | F12: 19791010 | G12: =DATE(INT(F12/10000),INT(MOD(F12,10000)/100),MOD(F12,100)) -> 29138 | H12: =DATEDIF(G12,$G$4,"Y") -> 41 | J12: 20000321 | K12: =DATE(INT(J12/10000),INT(MOD(J12,10000)/100),MOD(J12,100)) -> 36606 | L12: =DATEDIF(K12,$G$4,"Y") -> 21 | O12: 7 | P12: 22000 | Q12: 生産管理部ＩＴ管理課 | R12: 0 | T12: 2
A13: 25 | B13: 227 | C13: 3295 | D13: 菊地 由貴 | E13: L | F13: 19900327 | G13: =DATE(INT(F13/10000),INT(MOD(F13,10000)/100),MOD(F13,100)) -> 32959 | H13: =DATEDIF(G13,$G$4,"Y") -> 31 | J13: 20080321 | K13: =DATE(INT(J13/10000),INT(MOD(J13,10000)/100),MOD(J13,100)) -> 39528 | L13: =DATEDIF(K13,$G$4,"Y") -> 13 | O13: 6 | P13: 90000 | Q13: 資材部 | R13: 0 | T13: 2
A14: 9 | B14: 270 | C14: 3374 | D14: 吉田 綾那 | E14: L | F14: 19930406 | G14: =DATE(INT(F14/10000),INT(MOD(F14,10000)/100),MOD(F14,100)) -> 34065 | H14: =DATEDIF(G14,$G$4,"Y") -> 28 | J14: 20120321 | K14: =DATE(INT(J14/10000),INT(MOD(J14,10000)/100),MOD(J14,100)) -> 40989 | L14: =DATEDIF(K14,$G$4,"Y") -> 9 | O14: 6 | P14: 50000 | Q14: 品質保証部検査課 | R14: 0 | T14: 2
A15: 10 | B15: 348 | C15: 3496 | D15: 吉野 里咲 | E15: L | F15: 19990512 | G15: =DATE(INT(F15/10000),INT(MOD(F15,10000)/100),MOD(F15,100)) -> 36292 | H15: =DATEDIF(G15,$G$4,"Y") -> 22 | J15: 20180402 | K15: =DATE(INT(J15/10000),INT(MOD(J15,10000)/100),MOD(J15,100)) -> 43192 | L15: =DATEDIF(K15,$G$4,"Y") -> 3 | O15: 6 | P15: 50000 | Q15: 品質保証部検査課 | R15: 0 | T15: 2
A16: 12 | B16: 44 | C16: 1388 | D16: 久保田 弘子 | E16: L | F16: 19780106 | G16: =DATE(INT(F16/10000),INT(MOD(F16,10000)/100),MOD(F16,100)) -> 28496 | H16: =DATEDIF(G16,$G$4,"Y") -> 43 | J16: 20140908 | K16: =DATE(INT(J16/10000),INT(MOD(J16,10000)/100),MOD(J16,100)) -> 41890 | L16: =DATEDIF(K16,$G$4,"Y") -> 6 | O16: 6 | P16: 60200 | Q16: 生産管理部ＩＴ管理課(羽生) | R16: 0 | T16: 2
A17: 18 | B17: 274 | C17: 3383 | D17: 金成 智美 | E17: L | F17: 19931205 | G17: =DATE(INT(F17/10000),INT(MOD(F17,10000)/100),MOD(F17,100)) -> 34308 | H17: =DATEDIF(G17,$G$4,"Y") -> 27 | J17: 20120321 | K17: =DATE(INT(J17/10000),INT(MOD(J17,10000)/100),MOD(J17,100)) -> 40989 | L17: =DATEDIF(K17,$G$4,"Y") -> 9 | O17: 6 | P17: 63000 | Q17: 品質保証部（羽生） | R17: 0 | T17: 2
A18: 1 | B18: 19 | C18: 1343 | D18: 工藤 三枝子 | E18: L | F18: 19660702 | G18: =DATE(INT(F18/10000),INT(MOD(F18,10000)/100),MOD(F18,100)) -> 24290 | H18: =DATEDIF(G18,$G$4,"Y") -> 55 | J18: 19990818 | K18: =DATE(INT(J18/10000),INT(MOD(J18,10000)/100),MOD(J18,100)) -> 36390 | L18: =DATEDIF(K18,$G$4,"Y") -> 22 | O18: 7 | P18: 20000 | Q18: 生産管理部製品管理課 | R18: 0 | T18: 1
A19: 13 | B19: 119 | C19: 2955 | D19: 甲斐 昌美 | E19: L | F19: 19740816 | G19: =DATE(INT(F19/10000),INT(MOD(F19,10000)/100),MOD(F19,100)) -> 27257 | H19: =DATEDIF(G19,$G$4,"Y") -> 47 | J19: 19930322 | K19: =DATE(INT(J19/10000),INT(MOD(J19,10000)/100),MOD(J19,100)) -> 34050 | L19: =DATEDIF(K19,$G$4,"Y") -> 28 | O19: 6 | P19: 61000 | Q19: 生産技術部（羽生） | R19: 0 | T19: 2
A20: 23 | B20: 219 | C20: 3268 | D20: 高谷 梓代 | E20: L | F20: 19880517 | G20: =DATE(INT(F20/10000),INT(MOD(F20,10000)/100),MOD(F20,100)) -> 32280 | H20: =DATEDIF(G20,$G$4,"Y") -> 33 | J20: 20070321 | K20: =DATE(INT(J20/10000),INT(MOD(J20,10000)/100),MOD(J20,100)) -> 39162 | L20: =DATEDIF(K20,$G$4,"Y") -> 14 | O20: 6 | P20: 60100 | Q20: 生産管理部調達課(羽生) | R20: 0 | T20: 2
A21: 7 | B21: 43 | C21: 1387 | D21: 高麗 美那 | E21: L | F21: 19851216 | G21: =DATE(INT(F21/10000),INT(MOD(F21,10000)/100),MOD(F21,100)) -> 31397 | H21: =DATEDIF(G21,$G$4,"Y") -> 35 | J21: 20140506 | K21: =DATE(INT(J21/10000),INT(MOD(J21,10000)/100),MOD(J21,100)) -> 41765 | L21: =DATEDIF(K21,$G$4,"Y") -> 7 | O21: 6 | P21: 44200 | Q21: 川越第二工場管理 | R21: 0 | T21: 2
A22: 24 | B22: 228 | C22: 3296 | D22: 斎藤 満美 | E22: L | F22: 19891227 | G22: =DATE(INT(F22/10000),INT(MOD(F22,10000)/100),MOD(F22,100)) -> 32869 | H22: =DATEDIF(G22,$G$4,"Y") -> 31 | J22: 20080321 | K22: =DATE(INT(J22/10000),INT(MOD(J22,10000)/100),MOD(J22,100)) -> 39528 | L22: =DATEDIF(K22,$G$4,"Y") -> 13 | O22: 6 | P22: 21000 | Q22: 生産管理部調達課 | R22: 0 | T22: 2
A23: 17 | B23: 328 | C23: 3470 | D23: 山口 未羽 | E23: L | F23: 19980223 | G23: =DATE(INT(F23/10000),INT(MOD(F23,10000)/100),MOD(F23,100)) -> 35849 | H23: =DATEDIF(G23,$G$4,"Y") -> 23 | J23: 20160401 | K23: =DATE(INT(J23/10000),INT(MOD(J23,10000)/100),MOD(J23,100)) -> 42461 | L23: =DATEDIF(K23,$G$4,"Y") -> 5 | O23: 6 | P23: 69211 | Q23: 羽生工場ＢＰＶ | R23: 1 | S23: ＊ | T23: 2
A24: 5 | B24: 331 | C24: 3475 | D24: 山田 季生 | E24: L | F24: 19981006 | G24: =DATE(INT(F24/10000),INT(MOD(F24,10000)/100),MOD(F24,100)) -> 36074 | H24: =DATEDIF(G24,$G$4,"Y") -> 22 | J24: 20170403 | K24: =DATE(INT(J24/10000),INT(MOD(J24,10000)/100),MOD(J24,100)) -> 42828 | L24: =DATEDIF(K24,$G$4,"Y") -> 4 | O24: 6 | P24: 31000 | Q24: 生産技術部２課工機係 | R24: 0 | T24: 2
A25: 13 | B25: 277 | C25: 3386 | D25: 山本 七海 | E25: L | F25: 19940104 | G25: =DATE(INT(F25/10000),INT(MOD(F25,10000)/100),MOD(F25,100)) -> 34338 | H25: =DATEDIF(G25,$G$4,"Y") -> 27 | J25: 20120321 | K25: =DATE(INT(J25/10000),INT(MOD(J25,10000)/100),MOD(J25,100)) -> 40989 | L25: =DATEDIF(K25,$G$4,"Y") -> 9 | O25: 6 | P25: 66011 | Q25: 羽生工場ＶＰ－２ | R25: 1 | S25: ＊ | T25: 2
A26: 12 | B26: 21 | C26: 1346 | D26: 漆原 景子 | E26: L | F26: 19890318 | G26: =DATE(INT(F26/10000),INT(MOD(F26,10000)/100),MOD(F26,100)) -> 32585 | H26: =DATEDIF(G26,$G$4,"Y") -> 32 | J26: 20080321 | K26: =DATE(INT(J26/10000),INT(MOD(J26,10000)/100),MOD(J26,100)) -> 39528 | L26: =DATEDIF(K26,$G$4,"Y") -> 13 | O26: 6 | P26: 66011 | Q26: 羽生工場ＶＰ－２ | R26: 1 | S26: ＊ | T26: 2
A27: 19 | B27: 129 | C27: 2990 | D27: 春山 智津子 | E27: L | F27: 19730517 | G27: =DATE(INT(F27/10000),INT(MOD(F27,10000)/100),MOD(F27,100)) -> 26801 | H27: =DATEDIF(G27,$G$4,"Y") -> 48 | J27: 19940322 | K27: =DATE(INT(J27/10000),INT(MOD(J27,10000)/100),MOD(J27,100)) -> 34415 | L27: =DATEDIF(K27,$G$4,"Y") -> 27 | O27: 7 | P27: 80000 | Q27: ＮＥＬ | R27: 0 | T27: 2
A28: 21 | B28: 257 | C28: 3354 | D28: 諸星 美咲 | E28: L | F28: 19930128 | G28: =DATE(INT(F28/10000),INT(MOD(F28,10000)/100),MOD(F28,100)) -> 33997 | H28: =DATEDIF(G28,$G$4,"Y") -> 28 | J28: 20110321 | K28: =DATE(INT(J28/10000),INT(MOD(J28,10000)/100),MOD(J28,100)) -> 40623 | L28: =DATEDIF(K28,$G$4,"Y") -> 10 | O28: 6 | P28: 80000 | Q28: ＮＥＬ | R28: 0 | T28: 2
A29: 3 | B29: 162 | C29: 3117 | D29: 小笠原 智恵 | E29: L | F29: 19780329 | G29: =DATE(INT(F29/10000),INT(MOD(F29,10000)/100),MOD(F29,100)) -> 28578 | H29: =DATEDIF(G29,$G$4,"Y") -> 43 | J29: 19960321 | K29: =DATE(INT(J29/10000),INT(MOD(J29,10000)/100),MOD(J29,100)) -> 35145 | L29: =DATEDIF(K29,$G$4,"Y") -> 25 | O29: 6 | P29: 43211 | Q29: 本社工場ＢＶ | R29: 1 | S29: ＊ | T29: 2
A30: 11 | B30: 319 | C30: 3455 | D30: 小室 柚衣 | E30: L | F30: 19940120 | G30: =DATE(INT(F30/10000),INT(MOD(F30,10000)/100),MOD(F30,100)) -> 34354 | H30: =DATEDIF(G30,$G$4,"Y") -> 27 | J30: 20160401 | K30: =DATE(INT(J30/10000),INT(MOD(J30,10000)/100),MOD(J30,100)) -> 42461 | L30: =DATEDIF(K30,$G$4,"Y") -> 5 | O30: 8 | P30: 60000 | Q30: 生産管理部製品管理課(羽生) | R30: 0 | T30: 2
A31: 8 | B31: 336 | C31: 3481 | D31: 新井 由唯 | E31: L | F31: 19990103 | G31: =DATE(INT(F31/10000),INT(MOD(F31,10000)/100),MOD(F31,100)) -> 36163 | H31: =DATEDIF(G31,$G$4,"Y") -> 22 | J31: 20170403 | K31: =DATE(INT(J31/10000),INT(MOD(J31,10000)/100),MOD(J31,100)) -> 42828 | L31: =DATEDIF(K31,$G$4,"Y") -> 4 | O31: 6 | P31: 43211 | Q31: 本社工場ＢＶ | R31: 1 | S31: ＊ | T31: 2
A32: 16 | B32: 276 | C32: 3385 | D32: 水野 唯奈 | E32: L | F32: 19930929 | G32: =DATE(INT(F32/10000),INT(MOD(F32,10000)/100),MOD(F32,100)) -> 34241 | H32: =DATEDIF(G32,$G$4,"Y") -> 27 | J32: 20120321 | K32: =DATE(INT(J32/10000),INT(MOD(J32,10000)/100),MOD(J32,100)) -> 40989 | L32: =DATEDIF(K32,$G$4,"Y") -> 9 | O32: 6 | P32: 69011 | Q32: 羽生工場ＴＣ | R32: 1 | S32: ＊ | T32: 2
A33: 3 | B33: 150 | C33: 3062 | D33: 青木 博美 | E33: L | F33: 19750302 | G33: =DATE(INT(F33/10000),INT(MOD(F33,10000)/100),MOD(F33,100)) -> 27455 | H33: =DATEDIF(G33,$G$4,"Y") -> 46 | J33: 19950322 | K33: =DATE(INT(J33/10000),INT(MOD(J33,10000)/100),MOD(J33,100)) -> 34780 | L33: =DATEDIF(K33,$G$4,"Y") -> 26 | O33: 7 | P33: 3000 | Q33: 経理部経理課 | R33: 0 | T33: 2
A34: 22 | B34: 151 | C34: 3067 | D34: 斉藤 純子 | E34: L | F34: 19740821 | G34: =DATE(INT(F34/10000),INT(MOD(F34,10000)/100),MOD(F34,100)) -> 27262 | H34: =DATEDIF(G34,$G$4,"Y") -> 47 | J34: 19950322 | K34: =DATE(INT(J34/10000),INT(MOD(J34,10000)/100),MOD(J34,100)) -> 34780 | L34: =DATEDIF(K34,$G$4,"Y") -> 26 | O34: 7 | P34: 60000 | Q34: 生産管理部製品管理課(羽生) | R34: 0 | T34: 2
A35: 17 | B35: 413 | C35: 3950 | D35: 川島 洋子 | E35: L | F35: 19690713 | G35: =DATE(INT(F35/10000),INT(MOD(F35,10000)/100),MOD(F35,100)) -> 25397 | H35: =DATEDIF(G35,$G$4,"Y") -> 52 | J35: 20060221 | K35: =DATE(INT(J35/10000),INT(MOD(J35,10000)/100),MOD(J35,100)) -> 38769 | L35: =DATEDIF(K35,$G$4,"Y") -> 15 | O35: 7 | P35: 63000 | Q35: 品質保証部（羽生） | R35: 0 | T35: 2
A36: 2 | B36: 94 | C36: 2785 | D36: 大野 陽子 | E36: L | F36: 19671216 | G36: =DATE(INT(F36/10000),INT(MOD(F36,10000)/100),MOD(F36,100)) -> 24822 | H36: =DATEDIF(G36,$G$4,"Y") -> 53 | J36: 19860324 | K36: =DATE(INT(J36/10000),INT(MOD(J36,10000)/100),MOD(J36,100)) -> 31495 | L36: =DATEDIF(K36,$G$4,"Y") -> 35 | O36: 6 | P36: 22000 | Q36: 生産管理部ＩＴ管理課 | R36: 0 | T36: 2
A37: 16 | B37: 106 | C37: 2883 | D37: 中村 葉子 | E37: L | F37: 19710512 | G37: =DATE(INT(F37/10000),INT(MOD(F37,10000)/100),MOD(F37,100)) -> 26065 | H37: =DATEDIF(G37,$G$4,"Y") -> 50 | J37: 19900322 | K37: =DATE(INT(J37/10000),INT(MOD(J37,10000)/100),MOD(J37,100)) -> 32954 | L37: =DATEDIF(K37,$G$4,"Y") -> 31 | O37: 6 | P37: 63000 | Q37: 品質保証部（羽生） | R37: 0 | T37: 2
A38: 1 | B38: 356 | C38: 3505 | D38: 仲野 葵 | E38: L | F38: 20000510 | G38: =DATE(INT(F38/10000),INT(MOD(F38,10000)/100),MOD(F38,100)) -> 36656 | H38: =DATEDIF(G38,$G$4,"Y") -> 21 | J38: 20190401 | K38: =DATE(INT(J38/10000),INT(MOD(J38,10000)/100),MOD(J38,100)) -> 43556 | L38: =DATEDIF(K38,$G$4,"Y") -> 2 | O38: 6 | P38: 42411 | Q38: 本社工場組立第２ | R38: 1 | S38: ＊ | T38: 2
A39: 15 | B39: 256 | C39: 3353 | D39: 町田 汐理 | E39: L | F39: 19930317 | G39: =DATE(INT(F39/10000),INT(MOD(F39,10000)/100),MOD(F39,100)) -> 34045 | H39: =DATEDIF(G39,$G$4,"Y") -> 28 | J39: 20110321 | K39: =DATE(INT(J39/10000),INT(MOD(J39,10000)/100),MOD(J39,100)) -> 40623 | L39: =DATEDIF(K39,$G$4,"Y") -> 10 | O39: 6 | P39: 68111 | Q39: 羽生工場ＰＳＨ | R39: 1 | S39: ＊ | T39: 2
A40: 14 | B40: 311 | C40: 3446 | D40: 長谷川 桃花 | E40: L | F40: 19970303 | G40: =DATE(INT(F40/10000),INT(MOD(F40,10000)/100),MOD(F40,100)) -> 35492 | H40: =DATEDIF(G40,$G$4,"Y") -> 24 | J40: 20150401 | K40: =DATE(INT(J40/10000),INT(MOD(J40,10000)/100),MOD(J40,100)) -> 42095 | L40: =DATEDIF(K40,$G$4,"Y") -> 6 | O40: 6 | P40: 61200 | Q40: 生産技術部工機（羽生） | R40: 0 | T40: 2
A41: 26 | B41: 233 | C41: 3306 | D41: 長谷川 麻央 | E41: L | F41: 19910207 | G41: =DATE(INT(F41/10000),INT(MOD(F41,10000)/100),MOD(F41,100)) -> 33276 | H41: =DATEDIF(G41,$G$4,"Y") -> 30 | J41: 20090323 | K41: =DATE(INT(J41/10000),INT(MOD(J41,10000)/100),MOD(J41,100)) -> 39895 | L41: =DATEDIF(K41,$G$4,"Y") -> 12 | O41: 6 | P41: 90000 | Q41: 資材部 | R41: 0 | T41: 2
...

Sheet 正社員
D2: 基準年月日
C3: 社員番号 | D3: 氏名 | E3: 性別 | F3: 生年月日 | J3: 入社 年月 | O3: 学歴 | P3: 部門 | Q3: 部門 | R3: 直間コード | S3: 直間コード | T3: 職専コード
G4: 44409 | P4: コード | Q4: 名
A5: 1 | B5: 61 | C5: 1408 | D5: 老沼 信彦 | E5: M | F5: 19630327 | G5: =DATE(INT(F5/10000),INT(MOD(F5,10000)/100),MOD(F5,100)) -> 23097 | H5: =DATEDIF(G5,$G$4,"Y") -> 58 | J5: 20200413 | K5: =DATE(INT(J5/10000),INT(MOD(J5,10000)/100),MOD(J5,100)) -> 43934 | L5: =DATEDIF(K5,$G$4,"Y") -> 1 | O5: 8 | P5: 1100 | Q5: 総務部羽生総務課 | R5: 0 | T5: 1 | AE5: =ROUNDDOWN(P5*1,0) -> 1100
A6: 2 | B6: 3 | C6: 1278 | D6: 高野 博司 | E6: M | F6: 19620707 | G6: =DATE(INT(F6/10000),INT(MOD(F6,10000)/100),MOD(F6,100)) -> 22834 | H6: =DATEDIF(G6,$G$4,"Y") -> 59 | J6: 19920130 | K6: =DATE(INT(J6/10000),INT(MOD(J6,10000)/100),MOD(J6,100)) -> 33633 | L6: =DATEDIF(K6,$G$4,"Y") -> 29 | O6: 8 | P6: 1000 | Q6: 総務部 | R6: 0 | T6: 1 | AE6: =ROUNDDOWN(P6*1,0) -> 1000
A7: 3 | B7: 404 | C7: 3936 | D7: 井出 雄三 | E7: M | F7: 19770909 | G7: =DATE(INT(F7/10000),INT(MOD(F7,10000)/100),MOD(F7,100)) -> 28377 | H7: =DATEDIF(G7,$G$4,"Y") -> 43 | J7: 20060221 | K7: =DATE(INT(J7/10000),INT(MOD(J7,10000)/100),MOD(J7,100)) -> 38769 | L7: =DATEDIF(K7,$G$4,"Y") -> 15 | O7: 7 | P7: 1000 | Q7: 総務部 | R7: 0 | T7: 1 | AE7: =ROUNDDOWN(P7*1,0) -> 1000
A8: 4 | B8: 37 | C8: 1376 | D8: 山本 剛史 | E8: M | F8: 19811204 | G8: =DATE(INT(F8/10000),INT(MOD(F8,10000)/100),MOD(F8,100)) -> 29924 | H8: =DATEDIF(G8,$G$4,"Y") -> 39 | J8: 20120221 | K8: =DATE(INT(J8/10000),INT(MOD(J8,10000)/100),MOD(J8,100)) -> 40960 | L8: =DATEDIF(K8,$G$4,"Y") -> 9 | O8: 8 | P8: 1000 | Q8: 総務部 | R8: 0 | T8: 1 | AE8: =ROUNDDOWN(P8*1,0) -> 1000
A9: 5 | B9: 53 | C9: 1399 | D9: 松原 幸生 | E9: M | F9: 19660615 | G9: =DATE(INT(F9/10000),INT(MOD(F9,10000)/100),MOD(F9,100)) -> 24273 | H9: =DATEDIF(G9,$G$4,"Y") -> 55 | J9: 20181001 | K9: =DATE(INT(J9/10000),INT(MOD(J9,10000)/100),MOD(J9,100)) -> 43374 | L9: =DATEDIF(K9,$G$4,"Y") -> 2 | O9: 8 | P9: 1000 | Q9: 総務部 | R9: 0 | T9: 2 | AE9: =ROUNDDOWN(P9*1,0) -> 1000
A10: 6 | B10: 294 | C10: 3415 | D10: 味志 康平 | E10: M | F10: 19890705 | G10: =DATE(INT(F10/10000),INT(MOD(F10,10000)/100),MOD(F10,100)) -> 32694 | H10: =DATEDIF(G10,$G$4,"Y") -> 32 | J10: 20140321 | K10: =DATE(INT(J10/10000),INT(MOD(J10,10000)/100),MOD(J10,100)) -> 41719 | L10: =DATEDIF(K10,$G$4,"Y") -> 7 | O10: 8 | P10: 1100 | Q10: 総務部羽生総務課 | R10: 0 | T10: 1 | AE10: =ROUNDDOWN(P10*1,0) -> 1100
A11: 7 | B11: 262 | C11: 3361 | D11: 相馬 裕樹 | E11: M | F11: 19891109 | G11: =DATE(INT(F11/10000),INT(MOD(F11,10000)/100),MOD(F11,100)) -> 32821 | H11: =DATEDIF(G11,$G$4,"Y") -> 31 | J11: 20120321 | K11: =DATE(INT(J11/10000),INT(MOD(J11,10000)/100),MOD(J11,100)) -> 40989 | L11: =DATEDIF(K11,$G$4,"Y") -> 9 | O11: 8 | P11: 3000 | Q11: 経理部経理課 | R11: 0 | T11: 1 | AE11: =ROUNDDOWN(P11*1,0) -> 3000
A12: 8 | B12: 5 | C12: 1291 | D12: 石塚 隆司 | E12: M | F12: 19671101 | G12: =DATE(INT(F12/10000),INT(MOD(F12,10000)/100),MOD(F12,100)) -> 24777 | H12: =DATEDIF(G12,$G$4,"Y") -> 53 | J12: 19940322 | K12: =DATE(INT(J12/10000),INT(MOD(J12,10000)/100),MOD(J12,100)) -> 34415 | L12: =DATEDIF(K12,$G$4,"Y") -> 27 | O12: 8 | P12: 10000 | Q12: 営業部 | R12: 0 | T12: 1 | AE12: =ROUNDDOWN(P12*1,0) -> 10000
A13: 9 | B13: 12 | C13: 1323 | D13: 戸田 鉄也 | E13: M | F13: 19721018 | G13: =DATE(INT(F13/10000),INT(MOD(F13,10000)/100),MOD(F13,100)) -> 26590 | H13: =DATEDIF(G13,$G$4,"Y") -> 48 | J13: 20030506 | K13: =DATE(INT(J13/10000),INT(MOD(J13,10000)/100),MOD(J13,100)) -> 37747 | L13: =DATEDIF(K13,$G$4,"Y") -> 18 | O13: 8 | P13: 10000 | Q13: 営業部 | R13: 0 | T13: 1 | AE13: =ROUNDDOWN(P13*1,0) -> 10000
A14: 10 | B14: 192 | C14: 3210 | D14: 松本 和幸 | E14: M | F14: 19810520 | G14: =DATE(INT(F14/10000),INT(MOD(F14,10000)/100),MOD(F14,100)) -> 29726 | H14: =DATEDIF(G14,$G$4,"Y") -> 40 | J14: 20040322 | K14: =DATE(INT(J14/10000),INT(MOD(J14,10000)/100),MOD(J14,100)) -> 38068 | L14: =DATEDIF(K14,$G$4,"Y") -> 17 | O14: 8 | P14: 10000 | Q14: 営業部 | R14: 0 | T14: 1 | AE14: =ROUNDDOWN(P14*1,0) -> 10000
A15: 11 | B15: 51 | C15: 1397 | D15: 袴田 晴夫 | E15: M | F15: 19801023 | G15: =DATE(INT(F15/10000),INT(MOD(F15,10000)/100),MOD(F15,100)) -> 29517 | H15: =DATEDIF(G15,$G$4,"Y") -> 40 | J15: 20180201 | K15: =DATE(INT(J15/10000),INT(MOD(J15,10000)/100),MOD(J15,100)) -> 43132 | L15: =DATEDIF(K15,$G$4,"Y") -> 3 | O15: 8 | P15: 10000 | Q15: 営業部 | R15: 0 | T15: 1 | AE15: =ROUNDDOWN(P15*1,0) -> 10000
A16: 12 | B16: 244 | C16: 3331 | D16: 市川 学 | E16: M | F16: 19880505 | G16: =DATE(INT(F16/10000),INT(MOD(F16,10000)/100),MOD(F16,100)) -> 32268 | H16: =DATEDIF(G16,$G$4,"Y") -> 33 | J16: 20110321 | K16: =DATE(INT(J16/10000),INT(MOD(J16,10000)/100),MOD(J16,100)) -> 40623 | L16: =DATEDIF(K16,$G$4,"Y") -> 10 | O16: 8 | P16: 10000 | Q16: 営業部 | R16: 0 | T16: 1 | AE16: =ROUNDDOWN(P16*1,0) -> 10000
A17: 13 | B17: 351 | C17: 3500 | D17: 清水 優汰 | E17: M | F17: 19960812 | G17: =DATE(INT(F17/10000),INT(MOD(F17,10000)/100),MOD(F17,100)) -> 35289 | H17: =DATEDIF(G17,$G$4,"Y") -> 24 | J17: 20190401 | K17: =DATE(INT(J17/10000),INT(MOD(J17,10000)/100),MOD(J17,100)) -> 43556 | L17: =DATEDIF(K17,$G$4,"Y") -> 2 | O17: 8 | P17: 10000 | Q17: 営業部 | R17: 0 | T17: 2 | AE17: =ROUNDDOWN(P17*1,0) -> 10000
A18: 14 | B18: 344 | C18: 3491 | D18: 中村 友和 | E18: M | F18: 19950424 | G18: =DATE(INT(F18/10000),INT(MOD(F18,10000)/100),MOD(F18,100)) -> 34813 | H18: =DATEDIF(G18,$G$4,"Y") -> 26 | J18: 20180402 | K18: =DATE(INT(J18/10000),INT(MOD(J18,10000)/100),MOD(J18,100)) -> 43192 | L18: =DATEDIF(K18,$G$4,"Y") -> 3 | O18: 8 | P18: 10000 | Q18: 営業部 | R18: 0 | T18: 2 | AE18: =ROUNDDOWN(P18*1,0) -> 10000
AE19: =ROUNDDOWN(P19*1,0) -> 0
AE20: =ROUNDDOWN(P20*1,0) -> 0
H21: =SUM(H5:H20) -> 581 | I21: =H21/$A$18 -> 41.5 | L21: =SUM(L5:L20) -> 152 | M21: =L21/$A$18 -> 10.857143 | AE21: =ROUNDDOWN(P21*1,0) -> 0
AE22: =ROUNDDOWN(P22*1,0) -> 0
AE23: =ROUNDDOWN(P23*1,0) -> 0
A24: 1 | B24: 271 | C24: 3375 | D24: 立花 舞 | E24: L | F24: 19931205 | G24: =DATE(INT(F24/10000),INT(MOD(F24,10000)/100),MOD(F24,100)) -> 34308 | H24: =DATEDIF(G24,$G$4,"Y") -> 27 | J24: 20120321 | K24: =DATE(INT(J24/10000),INT(MOD(J24,10000)/100),MOD(J24,100)) -> 40989 | L24: =DATEDIF(K24,$G$4,"Y") -> 9 | O24: 6 | P24: 1000 | Q24: 総務部 | R24: 0 | T24: 2 | AE24: =ROUNDDOWN(P24*1,0) -> 1000
A25: 2 | B25: 130 | C25: 3002 | D25: 堤 松子 | E25: L | F25: 19760123 | G25: =DATE(INT(F25/10000),INT(MOD(F25,10000)/100),MOD(F25,100)) -> 27782 | H25: =DATEDIF(G25,$G$4,"Y") -> 45 | J25: 19940322 | K25: =DATE(INT(J25/10000),INT(MOD(J25,10000)/100),MOD(J25,100)) -> 34415 | L25: =DATEDIF(K25,$G$4,"Y") -> 27 | O25: 6 | P25: 1100 | Q25: 総務部羽生総務課 | R25: 0 | T25: 2 | AE25: =ROUNDDOWN(P25*1,0) -> 1100
A26: 3 | B26: 150 | C26: 3062 | D26: 青木 博美 | E26: L | F26: 19750302 | G26: =DATE(INT(F26/10000),INT(MOD(F26,10000)/100),MOD(F26,100)) -> 27455 | H26: =DATEDIF(G26,$G$4,"Y") -> 46 | J26: 19950322 | K26: =DATE(INT(J26/10000),INT(MOD(J26,10000)/100),MOD(J26,100)) -> 34780 | L26: =DATEDIF(K26,$G$4,"Y") -> 26 | O26: 7 | P26: 3000 | Q26: 経理部経理課 | R26: 0 | T26: 2 | AE26: =ROUNDDOWN(P26*1,0) -> 3000
A27: 4 | B27: 280 | C27: 3392 | D27: 木下 由紀子 | E27: L | F27: 19910308 | G27: =DATE(INT(F27/10000),INT(MOD(F27,10000)/100),MOD(F27,100)) -> 33305 | H27: =DATEDIF(G27,$G$4,"Y") -> 30 | J27: 20130321 | K27: =DATE(INT(J27/10000),INT(MOD(J27,10000)/100),MOD(J27,100)) -> 41354 | L27: =DATEDIF(K27,$G$4,"Y") -> 8 | O27: 8 | P27: 3000 | Q27: 経理部経理課 | R27: 0 | T27: 2 | AE27: =ROUNDDOWN(P27*1,0) -> 3000
A28: 5 | B28: 112 | C28: 2912 | D28: 尾崎 洋子 | E28: L | F28: 19731124 | G28: =DATE(INT(F28/10000),INT(MOD(F28,10000)/100),MOD(F28,100)) -> 26992 | H28: =DATEDIF(G28,$G$4,"Y") -> 47 | J28: 19920323 | K28: =DATE(INT(J28/10000),INT(MOD(J28,10000)/100),MOD(J28,100)) -> 33686 | L28: =DATEDIF(K28,$G$4,"Y") -> 29 | O28: 6 | P28: 10000 | Q28: 営業部 | R28: 0 | T28: 2 | AE28: =ROUNDDOWN(P28*1,0) -> 10000
A29: 6 | B29: 229 | C29: 3297 | D29: 羽鳥 麻里 | E29: L | F29: 19900313 | G29: =DATE(INT(F29/10000),INT(MOD(F29,10000)/100),MOD(F29,100)) -> 32945 | H29: =DATEDIF(G29,$G$4,"Y") -> 31 | J29: 20080321 | K29: =DATE(INT(J29/10000),INT(MOD(J29,10000)/100),MOD(J29,100)) -> 39528 | L29: =DATEDIF(K29,$G$4,"Y") -> 13 | O29: 6 | P29: 10000 | Q29: 営業部 | R29: 0 | T29: 2 | AE29: =ROUNDDOWN(P29*1,0) -> 10000
A30: 7 | B30: 62 | C30: 1410 | D30: 石田 詩織 | E30: L | F30: 19941107 | G30: =DATE(INT(F30/10000),INT(MOD(F30,10000)/100),MOD(F30,100)) -> 34645 | H30: =DATEDIF(G30,$G$4,"Y") -> 26 | J30: 20200922 | K30: =DATE(INT(J30/10000),INT(MOD(J30,10000)/100),MOD(J30,100)) -> 44096 | L30: =DATEDIF(K30,$G$4,"Y") -> 0 | O30: 8 | P30: 10000 | Q30: 営業部 | R30: 0 | T30: 2 | AE30: =ROUNDDOWN(P30*1,0) -> 10000
AE31: =ROUNDDOWN(P31*1,0) -> 0
H32: =SUM(H24:H30) -> 252 | I32: =H32/$A$30 -> 36 | L32: =SUM(L24:L30) -> 112 | M32: =L32/$A$30 -> 16 | AE32: =ROUNDDOWN(P32*1,0) -> 0
AE33: =ROUNDDOWN(P33*1,0) -> 0
AE34: =ROUNDDOWN(P34*1,0) -> 0
AE35: =ROUNDDOWN(P35*1,0) -> 0
A36: 1 | B36: 436 | C36: 3992 | D36: 富岡 広樹 | E36: M | F36: 19750708 | G36: =DATE(INT(F36/10000),INT(MOD(F36,10000)/100),MOD(F36,100)) -> 27583 | H36: =DATEDIF(G36,$G$4,"Y") -> 46 | J36: 20071211 | K36: =DATE(INT(J36/10000),INT(MOD(J36,10000)/100),MOD(J36,100)) -> 39427 | L36: =DATEDIF(K36,$G$4,"Y") -> 13 | O36: 8 | P36: 80000 | Q36: ＮＥＬ | R36: 0 | T36: 1 | AE36: =ROUNDDOWN(P36*1,0) -> 80000
A37: 2 | B37: 4 | C37: 1290 | D37: 正木 成彦 | E37: M | F37: 19650109 | G37: =DATE(INT(F37/10000),INT(MOD(F37,10000)/100),MOD(F37,100)) -> 23751 | H37: =DATEDIF(G37,$G$4,"Y") -> 56 | J37: 19940321 | K37: =DATE(INT(J37/10000),INT(MOD(J37,10000)/100),MOD(J37,100)) -> 34414 | L37: =DATEDIF(K37,$G$4,"Y") -> 27 | O37: 8 | P37: 20000 | Q37: 生産管理部製品管理課 | R37: 0 | T37: 1 | AE37: =ROUNDDOWN(P37*1,0) -> 20000
A38: 3 | B38: 16 | C38: 1340 | D38: 田村 一裕 | E38: M | F38: 19750827 | G38: =DATE(INT(F38/10000),INT(MOD(F38,10000)/100),MOD(F38,100)) -> 27633 | H38: =DATEDIF(G38,$G$4,"Y") -> 45 | J38: 20060306 | K38: =DATE(INT(J38/10000),INT(MOD(J38,10000)/100),MOD(J38,100)) -> 38782 | L38: =DATEDIF(K38,$G$4,"Y") -> 15 | O38: 8 | P38: 20000 | Q38: 生産管理部製品管理課 | R38: 0 | T38: 1 | AE38: =ROUNDDOWN(P38*1,0) -> 20000
A39: 4 | B39: 208 | C39: 3248 | D39: 丹羽 一真 | E39: M | F39: 19840203 | G39: =DATE(INT(F39/10000),INT(MOD(F39,10000)/100),MOD(F39,100)) -> 30715 | H39: =DATEDIF(G39,$G$4,"Y") -> 37 | J39: 20060321 | K39: =DATE(INT(J39/10000),INT(MOD(J39,10000)/100),MOD(J39,100)) -> 38797 | L39: =DATEDIF(K39,$G$4,"Y") -> 15 | O39: 8 | P39: 20000 | Q39: 生産管理部製品管理課 | R39: 0 | T39: 1 | AE39: =ROUNDDOWN(P39*1,0) -> 20000
A40: 5 | B40: 131 | C40: 3007 | D40: 飯塚 誠 | E40: M | F40: 19730203 | G40: =DATE(INT(F40/10000),INT(MOD(F40,10000)/100),MOD(F40,100)) -> 26698 | H40: =DATEDIF(G40,$G$4,"Y") -> 48 | J40: 19950322 | K40: =DATE(INT(J40/10000),INT(MOD(J40,10000)/100),MOD(J40,100)) -> 34780 | L40: =DATEDIF(K40,$G$4,"Y") -> 26 | O40: 8 | P40: 22000 | Q40: 生産管理部ＩＴ管理課 | R40: 0 | T40: 1 | AE40: =ROUNDDOWN(P40*1,0) -> 22000
A41: 6 | B41: 128 | C41: 2984 | D41: 中條 幸一 | E41: M | F41: 19740128 | G41: =DATE(INT(F41/10000),INT(MOD(F41,10000)/100),MOD(F41,100)) -> 27057 | H41: =DATEDIF(G41,$G$4,"Y") -> 47 | J41: 19940322 | K41: =DATE(INT(J41/10000),INT(MOD(J41,10000)/100),MOD(J41,100)) -> 34415 | L41: =DATEDIF(K41,$G$4,"Y") -> 27 | O41: 7 | P41: 22000 | Q41: 生産管理部ＩＴ管理課 | R41: 0 | T41: 1 | AE41: =ROUNDDOWN(P41*1,0) -> 22000
...

Sheet 7月
E1: 理事、役員、顧問、海外出向者は除く
E3: 2021年7月1日従業員人数
A4: 部署コード | D4: 部署名 | E4: 正社員 | G4: 計 | H4: パ・嘱 | I4: 合計 | J4: 委託 | K4: 総合計
E5: M | F5: L
A6: 200 | D6: =VLOOKUP(A6,正社員!$P$3:$Q$20,2,FALSE) -> #N/A | E6: =COUNTIFS(正社員!$E$5:$P$20,A6) -> 0 | F6: =COUNTIF(正社員!$P$26:$P$32,A6) -> 0 | G6: =E6+F6 -> 0 | H6: =COUNTIF(#REF!,B6) -> #REF! | K6: =G6+H6+J6 -> #REF!
A7: 210 | D7: =VLOOKUP(A7,正社員!$P$3:$Q$20,2,FALSE) -> #N/A | E7: =COUNTIFS(正社員!$E$5:$P$20,A7) -> 0 | F7: =COUNTIF(正社員!$P$26:$P$32,A7) -> 0 | G7: =E7+F7 -> 0 | H7: =COUNTIF(#REF!,B7) -> #REF! | K7: =G7+H7+J7 -> #REF!
A8: 10000 | B8: 10020 | D8: =VLOOKUP(A8,正社員!$P$3:$Q$20,2,FALSE) -> 営業部 | E8: =COUNTIFS(正社員!$E$5:$P$18,A8) -> 7 | F8: =COUNTIF(正社員!$P$26:$P$32,A8) -> 3 | G8: =E8+F8 -> 10 | H8: =COUNTIF(#REF!,B8) -> #REF! | K8: =G8+H8+J8 -> #REF!
A9: 11000 | B9: 11020 | D9: =VLOOKUP(A9,正社員!$P$3:$Q$20,2,FALSE) -> #N/A | E9: =COUNTIFS(正社員!$E$5:$P$18,A9) -> 0 | F9: =COUNTIF(正社員!$P$26:$P$32,A9) -> 0 | G9: =E9+F9 -> 0 | H9: =COUNTIF(#REF!,B9) -> #REF! | K9: =G9+H9+J9 -> #REF!
A10: 90000 | B10: 90020 | D10: =VLOOKUP(A10,正社員!$P$39:$Q$195,2,FALSE) -> 資材部 | E10: =COUNTIFS(正社員!$P$38:$P$195,A10) -> 8 | F10: =COUNTIF(正社員!$P$200:$P$226,A10) -> 2 | G10: =E10+F10 -> 10 | H10: =COUNTIF(#REF!,B10) -> #REF! | K10: =G10+H10+J10 -> #REF!
A11: 3000 | B11: 3020 | D11: =VLOOKUP(A11,正社員!$P$3:$Q$20,2,FALSE) -> 経理部経理課 | E11: =COUNTIFS(正社員!$E$5:$P$18,A11) -> 1 | F11: =COUNTIF(正社員!$P$26:$P$32,A11) -> 2 | G11: =E11+F11 -> 3 | H11: =COUNTIF(#REF!,B11) -> #REF! | K11: =G11+H11+J11 -> #REF!
A12: 1000 | B12: 1020 | D12: =VLOOKUP(A12,正社員!$P$3:$Q$20,2,FALSE) -> 総務部 | E12: =COUNTIFS(正社員!$E$5:$P$20,A12) -> 4 | F12: =COUNTIF(正社員!$P$26:$P$32,A12) -> 0 | G12: =E12+F12 -> 4 | H12: =COUNTIF(#REF!,B12) -> #REF! | K12: =G12+H12+J12 -> #REF!
A13: 1100 | B13: 1120 | D13: =VLOOKUP(A13,正社員!$P$3:$Q$20,2,FALSE) -> 総務部羽生総務課 | E13: =COUNTIFS(正社員!$E$5:$P$20,A13) -> 2 | F13: =COUNTIF(正社員!$P$26:$P$32,A13) -> 0 | G13: =E13+F13 -> 2 | H13: =COUNTIF(#REF!,B13) -> #REF! | K13: =G13+H13+J13 -> #REF!
D14: 総務部計 | E14: =SUM(E12:E13) -> 6 | F14: =SUM(F12:F13) -> 0 | G14: =SUM(G12:G13) -> 6 | H14: =SUM(H12:H13) -> #REF! | I14: =SUM(I12:I13) -> 0 | J14: =SUM(J12:J13) -> 0 | K14: =SUM(K12:K13) -> #REF!
A15: 50000 | B15: 50020 | D15: =VLOOKUP(A15,正社員!$P$39:$Q$195,2,FALSE) -> 品質保証部検査課 | E15: =COUNTIFS(正社員!$P$38:$P$195,A15) -> 3 | F15: =COUNTIF(正社員!$P$200:$P$226,A15) -> 2 | G15: =E15+F15 -> 5 | H15: =COUNTIF(#REF!,B15) -> #REF! | K15: =G15+H15+J15 -> #REF!
A16: 51000 | B16: 51020 | D16: =VLOOKUP(A16,正社員!$P$39:$Q$195,2,FALSE) -> 品質保証部品質管理課 | E16: =COUNTIFS(正社員!$P$38:$P$195,A16) -> 7 | F16: =COUNTIF(正社員!$P$200:$P$226,A16) -> 0 | G16: =E16+F16 -> 7 | H16: =COUNTIF(#REF!,B16) -> #REF! | K16: =G16+H16+J16 -> #REF!
A17: 63000 | B17: 63020 | D17: =VLOOKUP(A17,正社員!$P$39:$Q$195,2,FALSE) -> 品質保証部（羽生） | E17: =COUNTIFS(正社員!$P$38:$P$195,A17) -> 7 | F17: =COUNTIF(正社員!$P$200:$P$226,A17) -> 3 | G17: =E17+F17 -> 10 | H17: =COUNTIF(#REF!,B17) -> #REF! | K17: =G17+H17+J17 -> #REF!
D18: 品質保証部計 | E18: =SUM(E15:E17) -> 17 | F18: =SUM(F15:F17) -> 5 | G18: =SUM(G15:G17) -> 22 | H18: =SUM(H15:H17) -> #REF! | I18: =SUM(I15:I17) -> 0 | J18: =SUM(J15:J17) -> 0 | K18: =SUM(K15:K17) -> #REF!
A19: 80000 | B19: 80020 | D19: =VLOOKUP(A19,正社員!$P$39:$Q$195,2,FALSE) -> ＮＥＬ | E19: =COUNTIFS(正社員!$P$38:$P$195,A19) -> 43 | F19: =COUNTIF(正社員!$P$200:$P$226,A19) -> 3 | G19: =E19+F19 -> 46 | H19: =COUNTIF(#REF!,B19) -> #REF! | K19: =G19+H19+J19 -> #REF!
A20: 41111 | B20: 41121 | C20: １課 | D20: =VLOOKUP(A20,正社員!$P$234:$Q$460,2,FALSE) -> 本社工場ＮＣ | E20: =COUNTIF(正社員!$P$234:$P$460,A20) -> 9 | F20: =COUNTIF(正社員!$P$467:$P$483,A20) -> 0 | G20: =E20+F20 -> 9 | H20: =COUNTIF(#REF!,B20) -> #REF! | K20: =G20+H20+J20 -> #REF!
A21: 43011 | B21: 43021 | D21: =VLOOKUP(A21,正社員!$P$234:$Q$460,2,FALSE) -> 本社工場ＴＰ | E21: =COUNTIF(正社員!$P$234:$P$460,A21) -> 14 | F21: =COUNTIF(正社員!$P$467:$P$483,A21) -> 0 | G21: =E21+F21 -> 14 | H21: =COUNTIF(#REF!,B21) -> #REF! | K21: =G21+H21+J21 -> #REF!
A22: 41011 | B22: 41021 | D22: =VLOOKUP(A22,正社員!$P$234:$Q$460,2,FALSE) -> 本社工場ＨＹ | E22: =COUNTIF(正社員!$P$234:$P$460,A22) -> 19 | F22: =COUNTIF(正社員!$P$467:$P$483,A22) -> 0 | G22: =E22+F22 -> 19 | H22: =COUNTIF(#REF!,B22) -> #REF! | K22: =G22+H22+J22 -> #REF!
A23: 42111 | B23: 42121 | C23: ２課 | D23: =VLOOKUP(A23,正社員!$P$234:$Q$460,2,FALSE) -> 本社工場組立第１ | E23: =COUNTIF(正社員!$P$234:$P$460,A23) -> 10 | F23: =COUNTIF(正社員!$P$467:$P$483,A23) -> 0 | G23: =E23+F23 -> 10 | H23: =COUNTIF(#REF!,B23) -> #REF! | K23: =G23+H23+J23 -> #REF!
A24: 42411 | B24: 42421 | D24: =VLOOKUP(A24,正社員!$P$234:$Q$460,2,FALSE) -> 本社工場組立第２ | E24: =COUNTIF(正社員!$P$234:$P$460,A24) -> 9 | F24: =COUNTIF(正社員!$P$467:$P$483,A24) -> 0 | G24: =E24+F24 -> 9 | H24: =COUNTIF(#REF!,B24) -> #REF! | K24: =G24+H24+J24 -> #REF!
A25: 42211 | B25: 42221 | D25: =VLOOKUP(A25,正社員!$P$234:$Q$460,2,FALSE) -> 本社工場ＡＣ研磨 | E25: =COUNTIF(正社員!$P$234:$P$460,A25) -> 11 | F25: =COUNTIF(正社員!$P$467:$P$483,A25) -> 0 | G25: =E25+F25 -> 11 | H25: =COUNTIF(#REF!,B25) -> #REF! | K25: =G25+H25+J25 -> #REF!
A26: 42011 | B26: 42021 | D26: =VLOOKUP(A26,正社員!$P$234:$Q$460,2,FALSE) -> 本社工場機械第１ | E26: =COUNTIF(正社員!$P$234:$P$460,A26) -> 13 | F26: =COUNTIF(正社員!$P$467:$P$483,A26) -> 0 | G26: =E26+F26 -> 13 | H26: =COUNTIF(#REF!,B26) -> #REF! | K26: =G26+H26+J26 -> #REF!
A27: 42311 | B27: 42321 | D27: =VLOOKUP(A27,正社員!$P$234:$Q$460,2,FALSE) -> 本社工場機械第２ | E27: =COUNTIF(正社員!$P$234:$P$460,A27) -> 7 | F27: =COUNTIF(正社員!$P$467:$P$483,A27) -> 0 | G27: =E27+F27 -> 7 | H27: =COUNTIF(#REF!,B27) -> #REF! | K27: =G27+H27+J27 -> #REF!
A28: 43211 | B28: 43221 | C28: ３課 | D28: =VLOOKUP(A28,正社員!$P$234:$Q$460,2,FALSE) -> 本社工場ＢＶ | E28: =COUNTIF(正社員!$P$234:$P$460,A28) -> 12 | F28: =COUNTIF(正社員!$P$467:$P$483,A28) -> 6 | G28: =E28+F28 -> 18 | H28: =COUNTIF(#REF!,B28) -> #REF! | K28: =G28+H28+J28 -> #REF!
A29: 43311 | B29: 43321 | D29: =VLOOKUP(A29,正社員!$P$234:$Q$460,2,FALSE) -> 本社工場ＳＰ | E29: =COUNTIF(正社員!$P$234:$P$460,A29) -> 4 | F29: =COUNTIF(正社員!$P$467:$P$483,A29) -> 0 | G29: =E29+F29 -> 4 | H29: =COUNTIF(#REF!,B29) -> #REF! | K29: =G29+H29+J29 -> #REF!
A30: 41200 | B30: 41221 | D30: =VLOOKUP(A30,正社員!$P$39:$Q$195,2,FALSE) -> 本社工場構内物流 | E30: =COUNTIFS(正社員!$P$38:$P$195,A30) -> 8 | F30: =COUNTIF(正社員!$P$200:$P$226,A30) -> 0 | G30: =E30+F30 -> 8 | H30: =COUNTIF(#REF!,B30) -> #REF! | K30: =G30+H30+J30 -> #REF!
A31: 40400 | B31: 40420 | D31: =VLOOKUP(A31,正社員!$P$39:$Q$195,2,FALSE) -> 本社工場改善 | E31: =COUNTIFS(正社員!$P$38:$P$195,A31) -> 4 | F31: =COUNTIF(正社員!$P$200:$P$226,A31) -> 0 | G31: =E31+F31 -> 4 | H31: =COUNTIF(#REF!,B31) -> #REF! | K31: =G31+H31+J31 -> #REF!
A32: 40000 | B32: 40020 | D32: =VLOOKUP(A32,正社員!$P$39:$Q$195,2,FALSE) -> 本社工場工場管理課 | E32: =COUNTIFS(正社員!$P$38:$P$195,A32) -> 8 | F32: =COUNTIF(正社員!$P$200:$P$226,A32) -> 1 | G32: =E32+F32 -> 9 | H32: =COUNTIF(#REF!,B32) -> #REF! | K32: =G32+H32+J32 -> #REF!
D33: 本社工場 | E33: =SUM(E20:E32) -> 128 | F33: =SUM(F20:F32) -> 7 | G33: =SUM(G20:G32) -> 135 | H33: =SUM(H20:H32) -> #REF! | I33: =SUM(I20:I32) -> 0 | J33: =SUM(J20:J32) -> 0 | K33: =SUM(K20:K32) -> #REF!
A34: 67211 | B34: 67221 | C34: １課 | D34: =VLOOKUP(A34,正社員!$P$234:$Q$460,2,FALSE) -> 羽生工場ＮＣ | E34: =COUNTIF(正社員!$P$234:$P$460,A34) -> 6 | F34: =COUNTIF(正社員!$P$467:$P$483,A34) -> 0 | G34: =E34+F34 -> 6 | H34: =COUNTIF(#REF!,B34) -> #REF! | K34: =G34+H34+J34 -> #REF!
A35: 68011 | B35: 68021 | D35: =VLOOKUP(A35,正社員!$P$234:$Q$460,2,FALSE) -> 羽生工場ＣＢ | E35: =COUNTIF(正社員!$P$234:$P$460,A35) -> 2 | F35: =COUNTIF(正社員!$P$467:$P$483,A35) -> 0 | G35: =E35+F35 -> 2 | H35: =COUNTIF(#REF!,B35) -> #REF! | K35: =G35+H35+J35 -> #REF!
A36: 69211 | B36: 69221 | D36: =VLOOKUP(A36,正社員!$P$234:$Q$460,2,FALSE) -> 羽生工場ＢＰＶ | E36: =COUNTIF(正社員!$P$234:$P$460,A36) -> 4 | F36: =COUNTIF(正社員!$P$467:$P$483,A36) -> 1 | G36: =E36+F36 -> 5 | H36: =COUNTIF(#REF!,B36) -> #REF! | K36: =G36+H36+J36 -> #REF!
A37: 69111 | B37: 69121 | D37: =VLOOKUP(A37,正社員!$P$234:$Q$460,2,FALSE) -> 羽生工場ＥＧＲ | E37: =COUNTIF(正社員!$P$234:$P$460,A37) -> 1 | F37: =COUNTIF(正社員!$P$467:$P$483,A37) -> 0 | G37: =E37+F37 -> 1 | H37: =COUNTIF(#REF!,B37) -> #REF! | K37: =G37+H37+J37 -> #REF!
A38: 64011 | B38: 64021 | C38: ２課 | D38: =VLOOKUP(A38,正社員!$P$234:$Q$460,2,FALSE) -> 羽生工場ＢＣ | E38: =COUNTIF(正社員!$P$234:$P$460,A38) -> 5 | F38: =COUNTIF(正社員!$P$467:$P$483,A38) -> 0 | G38: =E38+F38 -> 5 | H38: =COUNTIF(#REF!,B38) -> #REF! | K38: =G38+H38+J38 -> #REF!
A39: 64111 | B39: 64121 | D39: =VLOOKUP(A39,正社員!$P$234:$Q$460,2,FALSE) -> 羽生工場ＢＢ | E39: =COUNTIF(正社員!$P$234:$P$460,A39) -> 4 | F39: =COUNTIF(正社員!$P$467:$P$483,A39) -> 1 | G39: =E39+F39 -> 5 | H39: =COUNTIF(#REF!,B39) -> #REF! | K39: =G39+H39+J39 -> #REF!
A40: 64211 | B40: 64221 | D40: =VLOOKUP(A40,正社員!$P$234:$Q$460,2,FALSE) -> 羽生工場ＡＳ | E40: =COUNTIF(正社員!$P$234:$P$460,A40) -> 1 | F40: =COUNTIF(正社員!$P$467:$P$483,A40) -> 1 | G40: =E40+F40 -> 2 | H40: =COUNTIF(#REF!,B40) -> #REF! | K40: =G40+H40+J40 -> #REF!
A41: 67011 | B41: 67021 | D41: =VLOOKUP(A41,正社員!$P$234:$Q$460,2,FALSE) -> 羽生工場プレス | E41: =COUNTIF(正社員!$P$234:$P$460,A41) -> 9 | F41: =COUNTIF(正社員!$P$467:$P$483,A41) -> 0 | G41: =E41+F41 -> 9 | H41: =COUNTIF(#REF!,B41) -> #REF! | K41: =G41+H41+J41 -> #REF!
...

Sheet 参考
E1: 理事、役員、顧問、海外出向者は除く
D3: 2021年7月1日従業員人数
A4: 部署コード | D4: 部署名 | E4: 正社員 | G4: 計 | H4: パ・嘱 | I4: 合計 | J4: 委託 | K4: 総合計
E5: M | F5: L
A6: 200 | B6: 202 | D6: =VLOOKUP(A6,正社員!$P$3:$Q$20,2,FALSE) -> #N/A | E6: =COUNTIF(参考1男性!$C$5:$P$367,A6) -> 0 | F6: =COUNTIF(参考2女性!$C$5:$Q$52,A6) -> 0 | G6: =E6+F6 -> 0 | H6: =COUNTIF(参考3パート嘱託!$C$4:$Q$69,B6) -> 0 | I6: =SUM(G6:H6) -> 0 | K6: =G6+H6+J6 -> 0
A7: 210 | B7: 211 | D7: =VLOOKUP(A7,正社員!$P$3:$Q$20,2,FALSE) -> #N/A | E7: =COUNTIF(参考1男性!$C$5:$P$367,A7) -> 0 | F7: =COUNTIF(参考2女性!$C$5:$Q$52,A7) -> 0 | G7: =E7+F7 -> 0 | H7: =COUNTIF(参考3パート嘱託!$C$4:$Q$69,B7) -> 0 | I7: =SUM(G7:H7) -> 0 | K7: =G7+H7+J7 -> 0
A8: 10000 | B8: 10020 | D8: =VLOOKUP(A8,正社員!$P$3:$Q$20,2,FALSE) -> 営業部 | E8: =COUNTIF(参考1男性!$C$5:$P$367,A8) -> 7 | F8: =COUNTIF(参考2女性!$C$5:$Q$52,A8) -> 4 | G8: =E8+F8 -> 11 | H8: =COUNTIF(参考3パート嘱託!$C$4:$Q$69,B8) -> 1 | I8: =SUM(G8:H8) -> 12 | K8: =G8+H8+J8 -> 12
A9: 11000 | B9: 11020 | D9: =VLOOKUP(A9,正社員!$P$3:$Q$20,2,FALSE) -> #N/A | E9: =COUNTIF(参考1男性!$C$5:$P$367,A9) -> 0 | F9: =COUNTIF(参考2女性!$C$5:$Q$52,A9) -> 0 | G9: =E9+F9 -> 0 | H9: =COUNTIF(参考3パート嘱託!$C$4:$Q$69,B9) -> 0 | I9: =SUM(G9:H9) -> 0 | K9: =G9+H9+J9 -> 0
A10: 90000 | B10: 90020 | D10: =VLOOKUP(A10,正社員!$P$39:$Q$195,2,FALSE) -> 資材部 | E10: =COUNTIF(参考1男性!$C$5:$P$367,A10) -> 0 | F10: =COUNTIF(参考2女性!$C$5:$Q$52,A10) -> 0 | G10: =E10+F10 -> 0 | H10: =COUNTIF(参考3パート嘱託!$C$4:$Q$69,B10) -> 0 | I10: =SUM(G10:H10) -> 0 | K10: =G10+H10+J10 -> 0
A11: 3000 | B11: 3020 | D11: 経営管理部 | E11: =COUNTIF(参考1男性!$C$5:$P$367,A11) -> 2 | F11: =COUNTIF(参考2女性!$C$5:$Q$52,A11) -> 2 | G11: =E11+F11 -> 4 | H11: =COUNTIF(参考3パート嘱託!$C$4:$Q$69,B11) -> 1 | I11: =SUM(G11:H11) -> 5 | K11: =G11+H11+J11 -> 5
A12: 1000 | B12: 1020 | D12: =VLOOKUP(A12,正社員!$P$3:$Q$20,2,FALSE) -> 総務部 | E12: =COUNTIF(参考1男性!$C$5:$P$367,A12) -> 5 | F12: =COUNTIF(参考2女性!$C$5:$Q$52,A12) -> 1 | G12: =E12+F12 -> 6 | H12: =COUNTIF(参考3パート嘱託!$C$4:$Q$69,B12) -> 1 | I12: =SUM(G12:H12) -> 7 | K12: =G12+H12+J12 -> 7
A13: 1100 | B13: 1120 | D13: =VLOOKUP(A13,正社員!$P$3:$Q$20,2,FALSE) -> 総務部羽生総務課 | E13: =COUNTIF(参考1男性!$C$5:$P$367,A13) -> 1 | F13: =COUNTIF(参考2女性!$C$5:$Q$52,A13) -> 1 | G13: =E13+F13 -> 2 | H13: =COUNTIF(参考3パート嘱託!$C$4:$Q$69,B13) -> 1 | I13: =SUM(G13:H13) -> 3 | K13: =G13+H13+J13 -> 3
D14: 総務部計 | E14: =SUM(E12:E13) -> 6 | F14: =SUM(F12:F13) -> 2 | G14: =SUM(G12:G13) -> 8 | H14: =SUM(H12:H13) -> 2 | I14: =SUM(I12:I13) -> 10 | J14: =SUM(J12:J13) -> 0 | K14: =SUM(K12:K13) -> 10
A15: 50000 | B15: 50020 | D15: =VLOOKUP(A15,正社員!$P$39:$Q$195,2,FALSE) -> 品質保証部検査課 | E15: =COUNTIF(参考1男性!$C$5:$P$367,A15) -> 3 | F15: =COUNTIF(参考2女性!$C$5:$Q$52,A15) -> 2 | G15: =E15+F15 -> 5 | H15: =COUNTIF(参考3パート嘱託!$C$4:$Q$69,B15) -> 0 | I15: =SUM(G15:H15) -> 5 | K15: =G15+H15+J15 -> 5
A16: 51000 | B16: 51020 | D16: =VLOOKUP(A16,正社員!$P$39:$Q$195,2,FALSE) -> 品質保証部品質管理課 | E16: =COUNTIF(参考1男性!$C$5:$P$367,A16) -> 6 | F16: =COUNTIF(参考2女性!$C$5:$Q$52,A16) -> 0 | G16: =E16+F16 -> 6 | H16: =COUNTIF(参考3パート嘱託!$C$4:$Q$69,B16) -> 0 | I16: =SUM(G16:H16) -> 6 | K16: =G16+H16+J16 -> 6
A17: 63000 | B17: 63020 | D17: =VLOOKUP(A17,正社員!$P$39:$Q$195,2,FALSE) -> 品質保証部（羽生） | E17: =COUNTIF(参考1男性!$C$5:$P$367,A17) -> 9 | F17: =COUNTIF(参考2女性!$C$5:$Q$52,A17) -> 1 | G17: =E17+F17 -> 10 | H17: =COUNTIF(参考3パート嘱託!$C$4:$Q$69,B17) -> 0 | I17: =SUM(G17:H17) -> 10 | K17: =G17+H17+J17 -> 10
D18: 品質保証部計 | E18: =SUM(E15:E17) -> 18 | F18: =SUM(F15:F17) -> 3 | G18: =SUM(G15:G17) -> 21 | H18: =SUM(H15:H17) -> 0 | I18: =SUM(I15:I17) -> 21 | J18: =SUM(J15:J17) -> 0 | K18: =SUM(K15:K17) -> 21
A19: 80000 | B19: 80020 | D19: =VLOOKUP(A19,正社員!$P$39:$Q$195,2,FALSE) -> ＮＥＬ | E19: =COUNTIF(参考1男性!$C$5:$P$367,A19) -> 34 | F19: =COUNTIF(参考2女性!$C$5:$Q$52,A19) -> 3 | G19: =E19+F19 -> 37 | H19: =COUNTIF(参考3パート嘱託!$C$4:$Q$69,B19) -> 0 | I19: =SUM(G19:H19) -> 37 | K19: =G19+H19+J19 -> 37
A20: 41111 | B20: 41121 | C20: １課 | D20: =VLOOKUP(A20,正社員!$P$234:$Q$460,2,FALSE) -> 本社工場ＮＣ | E20: =COUNTIF(参考1男性!$C$5:$P$367,A20) -> 8 | F20: =COUNTIF(参考2女性!$C$5:$Q$52,A20) -> 0 | G20: =E20+F20 -> 8 | H20: =COUNTIF(参考3パート嘱託!$C$4:$Q$69,B20) -> 3 | I20: =SUM(G20:H20) -> 11 | K20: =G20+H20+J20 -> 11
A21: 43011 | B21: 43021 | D21: =VLOOKUP(A21,正社員!$P$234:$Q$460,2,FALSE) -> 本社工場ＴＰ | E21: =COUNTIF(参考1男性!$C$5:$P$367,A21) -> 17 | F21: =COUNTIF(参考2女性!$C$5:$Q$52,A21) -> 0 | G21: =E21+F21 -> 17 | H21: =COUNTIF(参考3パート嘱託!$C$4:$Q$69,B21) -> 2 | I21: =SUM(G21:H21) -> 19 | K21: =G21+H21+J21 -> 19
A22: 41011 | B22: 41021 | D22: =VLOOKUP(A22,正社員!$P$234:$Q$460,2,FALSE) -> 本社工場ＨＹ | E22: =COUNTIF(参考1男性!$C$5:$P$367,A22) -> 21 | F22: =COUNTIF(参考2女性!$C$5:$Q$52,A22) -> 0 | G22: =E22+F22 -> 21 | H22: =COUNTIF(参考3パート嘱託!$C$4:$Q$69,B22) -> 3 | I22: =SUM(G22:H22) -> 24 | K22: =G22+H22+J22 -> 24
A23: 42111 | B23: 42121 | C23: ２課 | D23: =VLOOKUP(A23,正社員!$P$234:$Q$460,2,FALSE) -> 本社工場組立第１ | E23: =COUNTIF(参考1男性!$C$5:$P$367,A23) -> 14 | F23: =COUNTIF(参考2女性!$C$5:$Q$52,A23) -> 1 | G23: =E23+F23 -> 15 | H23: =COUNTIF(参考3パート嘱託!$C$4:$Q$69,B23) -> 3 | I23: =SUM(G23:H23) -> 18 | K23: =G23+H23+J23 -> 18
A24: 42411 | B24: 42421 | D24: =VLOOKUP(A24,正社員!$P$234:$Q$460,2,FALSE) -> 本社工場組立第２ | E24: =COUNTIF(参考1男性!$C$5:$P$367,A24) -> 0 | F24: =COUNTIF(参考2女性!$C$5:$Q$52,A24) -> 0 | G24: =E24+F24 -> 0 | H24: =COUNTIF(参考3パート嘱託!$C$4:$Q$69,B24) -> 0 | I24: =SUM(G24:H24) -> 0 | K24: =G24+H24+J24 -> 0
A25: 42211 | B25: 42221 | D25: =VLOOKUP(A25,正社員!$P$234:$Q$460,2,FALSE) -> 本社工場ＡＣ研磨 | E25: =COUNTIF(参考1男性!$C$5:$P$367,A25) -> 11 | F25: =COUNTIF(参考2女性!$C$5:$Q$52,A25) -> 0 | G25: =E25+F25 -> 11 | H25: =COUNTIF(参考3パート嘱託!$C$4:$Q$69,B25) -> 1 | I25: =SUM(G25:H25) -> 12 | K25: =G25+H25+J25 -> 12
A26: 42011 | B26: 42021 | D26: =VLOOKUP(A26,正社員!$P$234:$Q$460,2,FALSE) -> 本社工場機械第１ | E26: =COUNTIF(参考1男性!$C$5:$P$367,A26) -> 10 | F26: =COUNTIF(参考2女性!$C$5:$Q$52,A26) -> 0 | G26: =E26+F26 -> 10 | H26: =COUNTIF(参考3パート嘱託!$C$4:$Q$69,B26) -> 1 | I26: =SUM(G26:H26) -> 11 | K26: =G26+H26+J26 -> 11
A27: 42311 | B27: 42321 | D27: =VLOOKUP(A27,正社員!$P$234:$Q$460,2,FALSE) -> 本社工場機械第２ | E27: =COUNTIF(参考1男性!$C$5:$P$367,A27) -> 6 | F27: =COUNTIF(参考2女性!$C$5:$Q$52,A27) -> 0 | G27: =E27+F27 -> 6 | H27: =COUNTIF(参考3パート嘱託!$C$4:$Q$69,B27) -> 0 | I27: =SUM(G27:H27) -> 6 | K27: =G27+H27+J27 -> 6
A28: 43211 | B28: 43221 | C28: ３課 | D28: =VLOOKUP(A28,正社員!$P$234:$Q$460,2,FALSE) -> 本社工場ＢＶ | E28: =COUNTIF(参考1男性!$C$5:$P$367,A28) -> 8 | F28: =COUNTIF(参考2女性!$C$5:$Q$52,A28) -> 6 | G28: =E28+F28 -> 14 | H28: =COUNTIF(参考3パート嘱託!$C$4:$Q$69,B28) -> 2 | I28: =SUM(G28:H28) -> 16 | K28: =G28+H28+J28 -> 16
A29: 43311 | B29: 43321 | D29: =VLOOKUP(A29,正社員!$P$234:$Q$460,2,FALSE) -> 本社工場ＳＰ | E29: =COUNTIF(参考1男性!$C$5:$P$367,A29) -> 3 | F29: =COUNTIF(参考2女性!$C$5:$Q$52,A29) -> 0 | G29: =E29+F29 -> 3 | H29: =COUNTIF(参考3パート嘱託!$C$4:$Q$69,B29) -> 2 | I29: =SUM(G29:H29) -> 5 | K29: =G29+H29+J29 -> 5
A30: 41200 | B30: 41220 | D30: =VLOOKUP(A30,正社員!$P$39:$Q$195,2,FALSE) -> 本社工場構内物流 | E30: =COUNTIF(参考1男性!$C$5:$P$367,A30) -> 8 | F30: =COUNTIF(参考2女性!$C$5:$Q$52,A30) -> 0 | G30: =E30+F30 -> 8 | H30: =COUNTIF(参考3パート嘱託!$C$4:$Q$69,B30) -> 2 | I30: =SUM(G30:H30) -> 10 | K30: =G30+H30+J30 -> 10
A31: 40400 | B31: 40420 | D31: =VLOOKUP(A31,正社員!$P$39:$Q$195,2,FALSE) -> 本社工場改善 | E31: =COUNTIF(参考1男性!$C$5:$P$367,A31) -> 3 | F31: =COUNTIF(参考2女性!$C$5:$Q$52,A31) -> 0 | G31: =E31+F31 -> 3 | H31: =COUNTIF(参考3パート嘱託!$C$4:$Q$69,B31) -> 1 | I31: =SUM(G31:H31) -> 4 | K31: =G31+H31+J31 -> 4
A32: 40000 | B32: 40020 | D32: =VLOOKUP(A32,正社員!$P$39:$Q$195,2,FALSE) -> 本社工場工場管理課 | E32: =COUNTIF(参考1男性!$C$5:$P$367,A32) -> 6 | F32: =COUNTIF(参考2女性!$C$5:$Q$52,A32) -> 1 | G32: =E32+F32 -> 7 | H32: =COUNTIF(参考3パート嘱託!$C$4:$Q$69,B32) -> 0 | I32: =SUM(G32:H32) -> 7 | K32: =G32+H32+J32 -> 7
D33: 本社工場 | E33: =SUM(E20:E32) -> 115 | F33: =SUM(F20:F32) -> 8 | G33: =SUM(G20:G32) -> 123 | H33: =SUM(H20:H32) -> 20 | I33: =SUM(I20:I32) -> 143 | J33: =SUM(J20:J32) -> 0 | K33: =SUM(K20:K32) -> 143
A34: 67211 | B34: 67221 | C34: １課 | D34: =VLOOKUP(A34,正社員!$P$234:$Q$460,2,FALSE) -> 羽生工場ＮＣ | E34: =COUNTIF(参考1男性!$C$5:$P$367,A34) -> 6 | F34: =COUNTIF(参考2女性!$C$5:$Q$52,A34) -> 0 | G34: =E34+F34 -> 6 | H34: =COUNTIF(参考3パート嘱託!$C$4:$Q$69,B34) -> 2 | I34: =SUM(G34:H34) -> 8 | K34: =G34+H34+J34 -> 8
A35: 68011 | B35: 68021 | D35: =VLOOKUP(A35,正社員!$P$234:$Q$460,2,FALSE) -> 羽生工場ＣＢ | E35: =COUNTIF(参考1男性!$C$5:$P$367,A35) -> 2 | F35: =COUNTIF(参考2女性!$C$5:$Q$52,A35) -> 0 | G35: =E35+F35 -> 2 | H35: =COUNTIF(参考3パート嘱託!$C$4:$Q$69,B35) -> 1 | I35: =SUM(G35:H35) -> 3 | K35: =G35+H35+J35 -> 3
A36: 69211 | B36: 69221 | D36: =VLOOKUP(A36,正社員!$P$234:$Q$460,2,FALSE) -> 羽生工場ＢＰＶ | E36: =COUNTIF(参考1男性!$C$5:$P$367,A36) -> 2 | F36: =COUNTIF(参考2女性!$C$5:$Q$52,A36) -> 0 | G36: =E36+F36 -> 2 | H36: =COUNTIF(参考3パート嘱託!$C$4:$Q$69,B36) -> 1 | I36: =SUM(G36:H36) -> 3 | K36: =G36+H36+J36 -> 3
A37: 69111 | B37: 69121 | D37: =VLOOKUP(A37,正社員!$P$234:$Q$460,2,FALSE) -> 羽生工場ＥＧＲ | E37: =COUNTIF(参考1男性!$C$5:$P$367,A37) -> 1 | F37: =COUNTIF(参考2女性!$C$5:$Q$52,A37) -> 0 | G37: =E37+F37 -> 1 | H37: =COUNTIF(参考3パート嘱託!$C$4:$Q$69,B37) -> 0 | I37: =SUM(G37:H37) -> 1 | K37: =G37+H37+J37 -> 1
